<?xml version="1.0" ?>
<!-- =================================================================================== -->
<!-- |    This document was autogenerated by xacro from dual_arm.xacro                 | -->
<!-- |    EDITING THIS FILE BY HAND IS NOT RECOMMENDED                                 | -->
<!-- =================================================================================== -->
<robot name="dualarm">
  <!-- ros_control plugin -->
  <gazebo>
    <plugin filename="libgazebo_ros_control.so" name="gazebo_ros_control">
      <robotNamespace>/dualarm</robotNamespace>
      <robotSimType>gazebo_ros_control/DefaultRobotHWSim</robotSimType>
      <controlPeriod>0.001</controlPeriod>
    </plugin>
  </gazebo>
  <!-- Base parts -->
  <link name="world"/>
  <joint name="base_joint" type="fixed">
    <origin rpy="0 0 0" xyz="0 0 0"/>
    <parent link="world"/>
    <child link="dual_arm_base_link"/>
  </joint>
  <link name="dual_arm_base_link"/>
  <joint name="dual_arm_base_joint" type="fixed">
    <origin rpy="0 0 0" xyz="0 0 0"/>
    <parent link="dual_arm_base_link"/>
    <child link="robot_base_link"/>
  </joint>
  <link name="robot_base_link">
    <inertial>
      <mass value="10.0"/>
      <origin rpy="0 0 0" xyz="0 0 0"/>
      <inertia ixx="0.0" ixy="0.0" ixz="0.0" iyy="0.0" iyz="0.0" izz="0.0"/>
    </inertial>
    <visual>
      <origin rpy="0 0 3.141592" xyz="0 0 0.3"/>
      <geometry>
        <mesh filename="package://dualarm_description/meshes/dualarm/base.STL" scale="0.001 0.001 0.001"/>
      </geometry>
    </visual>
  </link>
  <!-- waist part -->
  <joint name="dualarm_joint1" type="revolute">
    <axis xyz="0 0 -1"/>
    <limit effort="300" lower="-3.141592" upper="3.141592" velocity="6.283184"/>
    <origin rpy="0 0 0" xyz="0 0 0.652"/>
    <parent link="robot_base_link"/>
    <child link="link_01"/>
    <dynamics damping="0.1" friction="0.1"/>
  </joint>
  <transmission name="trans_dualarm_joint1">
    <type>transmission_interface/SimpleTransmission</type>
    <joint name="dualarm_joint1">
      <hardwareInterface>hardware_interface/EffortJointInterface</hardwareInterface>
    </joint>
    <actuator name="motor_dualarm_joint1">
      <hardwareInterface>hardware_interface/EffortJointInterface</hardwareInterface>
      <mechanicalReduction>1</mechanicalReduction>
    </actuator>
  </transmission>
  <link name="link_01">
    <inertial>
      <mass value="11.91"/>
      <origin rpy="0 0 0" xyz="-0.0001 -0.00305 0.09799"/>
      <inertia ixx="0.08385456343" ixy="-0.00013584154" ixz="-0.00062578735" iyy="0.07096937134" iyz="-0.01543280798" izz="0.05306201396"/>
    </inertial>
    <visual>
      <origin rpy="0 0 0" xyz="0 0 0"/>
      <geometry>
        <mesh filename="package://dualarm_description/meshes/dualarm1/link1.STL" scale="0.001 0.001 0.001"/>
      </geometry>
    </visual>
  </link>
  <joint name="dualarm_joint2" type="revolute">
    <axis xyz="0 -1 0"/>
    <limit effort="300" lower="-3.141592" upper="3.141592" velocity="6.283184"/>
    <origin rpy="0 0 0" xyz="0 0 0.148"/>
    <parent link="link_01"/>
    <child link="link_02"/>
    <dynamics damping="0.1" friction="0.1"/>
  </joint>
  <transmission name="trans_dualarm_joint2">
    <type>transmission_interface/SimpleTransmission</type>
    <joint name="dualarm_joint2">
      <hardwareInterface>hardware_interface/EffortJointInterface</hardwareInterface>
    </joint>
    <actuator name="motor_dualarm_joint2">
      <hardwareInterface>hardware_interface/EffortJointInterface</hardwareInterface>
      <mechanicalReduction>1</mechanicalReduction>
    </actuator>
  </transmission>
  <link name="link_02">
    <inertial>
      <mass value="9.901"/>
      <origin rpy="0 0 0" xyz="0.0010139 0.0036731 0.1436171"/>
      <inertia ixx="0.1408" ixy="0.0" ixz="0.0007" iyy="0.05" iyz="0.003643" izz="0.108"/>
    </inertial>
    <visual>
      <origin rpy="0 0 0" xyz="0 0 0"/>
      <geometry>
        <mesh filename="package://dualarm_description/meshes/dualarm/waist_2.STL" scale="0.001 0.001 0.001"/>
      </geometry>
    </visual>
  </link>
  <!--
	right_arm part
	-->
  <joint name="dualarm_joint3" type="revolute">
    <axis xyz="0 0 -1"/>
    <limit effort="300" lower="-3.141592" upper="3.141592" velocity="6.283184"/>
    <origin rpy="0 0 0" xyz="0 -0.125 0.217"/>
    <parent link="link_02"/>
    <child link="link_03"/>
    <dynamics damping="0.1" friction="0.1"/>
  </joint>
  <transmission name="trans_dualarm_joint3">
    <type>transmission_interface/SimpleTransmission</type>
    <joint name="dualarm_joint3">
      <hardwareInterface>hardware_interface/EffortJointInterface</hardwareInterface>
    </joint>
    <actuator name="motor_dualarm_joint3">
      <hardwareInterface>hardware_interface/EffortJointInterface</hardwareInterface>
      <mechanicalReduction>1</mechanicalReduction>
    </actuator>
  </transmission>
  <link name="link_03">
    <inertial>
      <mass value="3.35"/>
      <origin rpy="0 0 0" xyz="-0.0007 0.01789 0.06438"/>
      <inertia ixx="0.00915519492" ixy="0.0001638987" ixz="-5.218213e-05" iyy="0.00765665439" iyz="-0.00098169247" izz="0.0060237451"/>
    </inertial>
    <visual>
      <origin rpy="0 0 0" xyz="0 0 0"/>
      <geometry>
        <mesh filename="package://dualarm_description/meshes/dualarm1/link3.STL" scale="0.001 0.001 0.001"/>
      </geometry>
    </visual>
  </link>
  <joint name="dualarm_joint4" type="revolute">
    <axis xyz="0 1 0"/>
    <limit effort="300" lower="-3.141592" upper="3.141592" velocity="6.283184"/>
    <origin rpy="0 0 0" xyz="0 -0.09 0.083"/>
    <parent link="link_03"/>
    <child link="link_04"/>
    <dynamics damping="0.1" friction="0.1"/>
  </joint>
  <transmission name="trans_dualarm_joint4">
    <type>transmission_interface/SimpleTransmission</type>
    <joint name="dualarm_joint4">
      <hardwareInterface>hardware_interface/EffortJointInterface</hardwareInterface>
    </joint>
    <actuator name="motor_dualarm_joint4">
      <hardwareInterface>hardware_interface/EffortJointInterface</hardwareInterface>
      <mechanicalReduction>1</mechanicalReduction>
    </actuator>
  </transmission>
  <link name="link_04">
    <inertial>
      <mass value="3.51"/>
      <origin rpy="0 0 0" xyz="-0.00021 -0.07804 0.00077"/>
      <inertia ixx="0.01183318294" ixy="0.00024502838" ixz="-0.00012106848" iyy="0.00596380191" iyz="-8.120478e-05" izz="0.0126743791"/>
    </inertial>
    <visual>
      <origin rpy="0 0 0" xyz="0 0 0"/>
      <geometry>
        <mesh filename="package://dualarm_description/meshes/dualarm1/link4.STL" scale="0.001 0.001 0.001"/>
      </geometry>
    </visual>
  </link>
  <joint name="dualarm_joint5" type="revolute">
    <axis xyz="1 0 0"/>
    <limit effort="300" lower="-3.141592" upper="3.141592" velocity="6.283184"/>
    <origin rpy="0 0 0" xyz="0 -0.11 0"/>
    <parent link="link_04"/>
    <child link="link_05"/>
    <dynamics damping="0.1" friction="0.1"/>
  </joint>
  <transmission name="trans_dualarm_joint5">
    <type>transmission_interface/SimpleTransmission</type>
    <joint name="dualarm_joint5">
      <hardwareInterface>hardware_interface/EffortJointInterface</hardwareInterface>
    </joint>
    <actuator name="motor_dualarm_joint5">
      <hardwareInterface>hardware_interface/EffortJointInterface</hardwareInterface>
      <mechanicalReduction>1</mechanicalReduction>
    </actuator>
  </transmission>
  <link name="link_05">
    <inertial>
      <mass value="2.59"/>
      <origin rpy="0 0 0" xyz="-0.00254 -0.00018 -0.15039"/>
      <inertia ixx="0.01434915807" ixy="0.0" ixz="0.0" iyy="0.01595751714" iyz="-0.00112640495" izz="0.00381111816"/>
    </inertial>
    <visual>
      <origin rpy="0 0 0" xyz="0 0 0"/>
      <geometry>
        <mesh filename="package://dualarm_description/meshes/dualarm1/link5.STL" scale="0.001 0.001 0.001"/>
      </geometry>
    </visual>
  </link>
  <joint name="dualarm_joint6" type="revolute">
    <axis xyz="0 0 1"/>
    <limit effort="300" lower="-3.141592" upper="3.141592" velocity="6.283184"/>
    <origin rpy="0 0 0" xyz="0 0 -0.242"/>
    <parent link="link_05"/>
    <child link="link_06"/>
    <dynamics damping="0.1" friction="0.1"/>
  </joint>
  <transmission name="trans_dualarm_joint6">
    <type>transmission_interface/SimpleTransmission</type>
    <joint name="dualarm_joint6">
      <hardwareInterface>hardware_interface/EffortJointInterface</hardwareInterface>
    </joint>
    <actuator name="motor_dualarm_joint6">
      <hardwareInterface>hardware_interface/EffortJointInterface</hardwareInterface>
      <mechanicalReduction>1</mechanicalReduction>
    </actuator>
  </transmission>
  <link name="link_06">
    <inertial>
      <mass value="2.49"/>
      <origin rpy="0 0 0" xyz="-0.01909 0.00259 -0.10869"/>
      <inertia ixx="0.01230578809" ixy="0.0" ixz="0.00132629535" iyy="0.01094988937" iyz="-0.00032261465" izz="0.0036752981"/>
    </inertial>
    <visual>
      <origin rpy="0 0 0" xyz="0 0 0"/>
      <geometry>
        <mesh filename="package://dualarm_description/meshes/dualarm1/link6.STL" scale="0.001 0.001 0.001"/>
      </geometry>
    </visual>
  </link>
  <joint name="dualarm_joint7" type="revolute">
    <axis xyz="0 1 0"/>
    <limit effort="300" lower="-3.141592" upper="3.141592" velocity="6.283184"/>
    <origin rpy="0 0 0" xyz="-0.0245 0 -0.158"/>
    <parent link="link_06"/>
    <child link="link_07"/>
    <dynamics damping="0.1" friction="0.1"/>
  </joint>
  <transmission name="trans_dualarm_joint7">
    <type>transmission_interface/SimpleTransmission</type>
    <joint name="dualarm_joint7">
      <hardwareInterface>hardware_interface/EffortJointInterface</hardwareInterface>
    </joint>
    <actuator name="motor_dualarm_joint7">
      <hardwareInterface>hardware_interface/EffortJointInterface</hardwareInterface>
      <mechanicalReduction>1</mechanicalReduction>
    </actuator>
  </transmission>
  <link name="link_07">
    <inertial>
      <mass value="1.86"/>
      <origin rpy="0 0 0" xyz="0.02217 0.00213 -0.09649"/>
      <inertia ixx="0.00492717075" ixy="0.0" ixz="-0.00035330192" iyy="0.00407685409" iyz="0.00029876964" izz="0.00225029268"/>
    </inertial>
    <visual>
      <origin rpy="0 0 0" xyz="0 0 0"/>
      <geometry>
        <mesh filename="package://dualarm_description/meshes/dualarm1/link7.STL" scale="0.001 0.001 0.001"/>
      </geometry>
    </visual>
  </link>
  <joint name="dualarm_joint8" type="revolute">
    <axis xyz="0 0 1"/>
    <limit effort="300" lower="-3.141592" upper="3.141592" velocity="6.283184"/>
    <origin rpy="0 0 0" xyz="0.0245 0 -0.155"/>
    <parent link="link_07"/>
    <child link="link_08"/>
    <dynamics damping="0.1" friction="0.1"/>
  </joint>
  <transmission name="trans_dualarm_joint8">
    <type>transmission_interface/SimpleTransmission</type>
    <joint name="dualarm_joint8">
      <hardwareInterface>hardware_interface/EffortJointInterface</hardwareInterface>
    </joint>
    <actuator name="motor_dualarm_joint8">
      <hardwareInterface>hardware_interface/EffortJointInterface</hardwareInterface>
      <mechanicalReduction>1</mechanicalReduction>
    </actuator>
  </transmission>
  <link name="link_08">
    <inertial>
      <mass value="2.676"/>
      <origin rpy="0 0 0" xyz="0.00173 -0.00014 -0.13722"/>
      <inertia ixx="0.37276254112" ixy="-0.00341107392" ixz="0.00177705278" iyy="0.09113595607" iyz="-0.15665409162" izz="0.0032126267"/>
    </inertial>
    <visual>
      <origin rpy="0 0 0" xyz="0 0 0"/>
      <geometry>
        <mesh filename="package://dualarm_description/meshes/dualarm1/Wrist.STL" scale="0.001 0.001 0.001"/>
      </geometry>
    </visual>
  </link>
  <joint name="dualarm_joint9" type="revolute">
    <axis xyz="1 0 0"/>
    <limit effort="300" lower="-3.141592" upper="3.141592" velocity="6.283184"/>
    <origin rpy="0 0 0" xyz="0 0 -0.0755"/>
    <parent link="link_08"/>
    <child link="link_R_hand"/>
    <dynamics damping="0.1" friction="0.1"/>
  </joint>
  <transmission name="trans_dualarm_joint9">
    <type>transmission_interface/SimpleTransmission</type>
    <joint name="dualarm_joint9">
      <hardwareInterface>hardware_interface/EffortJointInterface</hardwareInterface>
    </joint>
    <actuator name="motor_dualarm_joint9">
      <hardwareInterface>hardware_interface/EffortJointInterface</hardwareInterface>
      <mechanicalReduction>1</mechanicalReduction>
    </actuator>
  </transmission>
  <link name="link_R_hand">
    <inertial>
      <mass value="1.29"/>
      <origin rpy="0 0 0" xyz="0 0 0"/>
      <inertia ixx="0.00753488339" ixy="0.0" ixz="0.0" iyy="0.00948557812" iyz="-0.00065921999" izz="0.02588099664"/>
    </inertial>
    <visual>
      <origin rpy="0 0 0" xyz="0 0 0"/>
      <geometry>
        <mesh filename="package://dualarm_description/meshes/dualarm1/Allegro_wrist.STL" scale="0.001 0.001 0.001"/>
      </geometry>
    </visual>
  </link>
  <joint name="dualarm_R_end" type="fixed">
    <origin rpy="0 0 0" xyz="0 0 -0.122"/>
    <parent link="link_R_hand"/>
    <child link="dualarm_R_end_frame"/>
  </joint>
  <link name="dualarm_R_end_frame"/>
  <!-- left_arm part-->
  <joint name="dualarm_joint10" type="revolute">
    <axis xyz="0 0 -1"/>
    <limit effort="300" lower="-1.570796" upper="1.570796" velocity="6.283184"/>
    <origin rpy="0 0 0" xyz="0 0.125 0.217"/>
    <parent link="link_02"/>
    <child link="link_10"/>
    <dynamics damping="0.1" friction="0.1"/>
  </joint>
  <transmission name="trans_dualarm_joint10">
    <type>transmission_interface/SimpleTransmission</type>
    <joint name="dualarm_joint10">
      <hardwareInterface>hardware_interface/EffortJointInterface</hardwareInterface>
    </joint>
    <actuator name="motor_dualarm_joint10">
      <hardwareInterface>hardware_interface/EffortJointInterface</hardwareInterface>
      <mechanicalReduction>1</mechanicalReduction>
    </actuator>
  </transmission>
  <link name="link_10">
    <inertial>
      <mass value="3.35"/>
      <origin rpy="0 0 0" xyz="-0.00087 0.017 0.064"/>
      <inertia ixx="0.0057" ixy="0.0" ixz="0.0" iyy="0.0055" iyz="-0.0005" izz="0.0044"/>
    </inertial>
    <visual>
      <origin rpy="0 0 3.141592" xyz="0 0 0"/>
      <geometry>
        <mesh filename="package://dualarm_description/meshes/dualarm1/link3.STL" scale="0.001 0.001 0.001"/>
      </geometry>
    </visual>
  </link>
  <joint name="dualarm_joint11" type="revolute">
    <axis xyz="0 -1 0"/>
    <limit effort="300" lower="-1.570796" upper="1.570796" velocity="6.283184"/>
    <origin rpy="0 0 0" xyz="0 0.09 0.083"/>
    <parent link="link_10"/>
    <child link="link_11"/>
    <dynamics damping="0.1" friction="0.1"/>
  </joint>
  <transmission name="trans_dualarm_joint11">
    <type>transmission_interface/SimpleTransmission</type>
    <joint name="dualarm_joint11">
      <hardwareInterface>hardware_interface/EffortJointInterface</hardwareInterface>
    </joint>
    <actuator name="motor_dualarm_joint11">
      <hardwareInterface>hardware_interface/EffortJointInterface</hardwareInterface>
      <mechanicalReduction>1</mechanicalReduction>
    </actuator>
  </transmission>
  <link name="link_11">
    <inertial>
      <mass value="3.51"/>
      <origin rpy="0 0 0" xyz="0.00089 0.07577 0.00053"/>
      <inertia ixx="0.01162556171" ixy="-7.354231e-05" ixz="0.00240453461" iyy="0.00634066394" iyz="0.81708848413" izz="0.0130982826"/>
    </inertial>
    <visual>
      <origin rpy="3.141592 0 0" xyz="0 -0.011 0"/>
      <geometry>
        <mesh filename="package://dualarm_description/meshes/dualarm1/link4.STL" scale="0.001 0.001 0.001"/>
      </geometry>
    </visual>
  </link>
  <joint name="dualarm_joint12" type="revolute">
    <axis xyz="1 0 0"/>
    <limit effort="200" lower="-0.785398" upper="1.570796" velocity="6.283184"/>
    <origin rpy="0 0 0" xyz="0 0.11 0"/>
    <parent link="link_11"/>
    <child link="link_12"/>
    <dynamics damping="0.1" friction="0.1"/>
  </joint>
  <transmission name="trans_dualarm_joint12">
    <type>transmission_interface/SimpleTransmission</type>
    <joint name="dualarm_joint12">
      <hardwareInterface>hardware_interface/EffortJointInterface</hardwareInterface>
    </joint>
    <actuator name="motor_dualarm_joint12">
      <hardwareInterface>hardware_interface/EffortJointInterface</hardwareInterface>
      <mechanicalReduction>1</mechanicalReduction>
    </actuator>
  </transmission>
  <link name="link_12">
    <inertial>
      <mass value="2.59"/>
      <origin rpy="0 0 0" xyz="-0.00238 0.00016 -0.15039"/>
      <inertia ixx="0.01434915775" ixy="0.0" ixz="-0.00111864019" iyy="0.01595929297" iyz="0.0007" izz="0.00381289368"/>
    </inertial>
    <visual>
      <origin rpy="0 0 0" xyz="0 0 0"/>
      <geometry>
        <mesh filename="package://dualarm_description/meshes/dualarm1/link5.STL" scale="0.001 0.001 0.001"/>
      </geometry>
    </visual>
  </link>
  <joint name="dualarm_joint13" type="revolute">
    <axis xyz="0 0 1"/>
    <limit effort="200" lower="-1.570796" upper="1.570796" velocity="6.283184"/>
    <origin rpy="0 0 0" xyz="0 0 -0.242"/>
    <parent link="link_12"/>
    <child link="link_13"/>
    <dynamics damping="0.1" friction="0.1"/>
  </joint>
  <transmission name="trans_dualarm_joint13">
    <type>transmission_interface/SimpleTransmission</type>
    <joint name="dualarm_joint13">
      <hardwareInterface>hardware_interface/EffortJointInterface</hardwareInterface>
    </joint>
    <actuator name="motor_dualarm_joint13">
      <hardwareInterface>hardware_interface/EffortJointInterface</hardwareInterface>
      <mechanicalReduction>1</mechanicalReduction>
    </actuator>
  </transmission>
  <link name="link_13">
    <inertial>
      <mass value="2.49"/>
      <origin rpy="0 0 0" xyz="-0.01891 -0.00275 -0.11422"/>
      <inertia ixx="0.01236605679" ixy="0.0" ixz="0.00131406231" iyy="0.01100446334" iyz="0.0" izz="0.0036703831"/>
    </inertial>
    <visual>
      <origin rpy="0 0 0" xyz="0 0 0"/>
      <geometry>
        <mesh filename="package://dualarm_description/meshes/dualarm1/link6.STL" scale="0.001 0.001 0.001"/>
      </geometry>
    </visual>
  </link>
  <joint name="dualarm_joint14" type="revolute">
    <axis xyz="0 -1 0"/>
    <limit effort="300" lower="-0.785398" upper="1.570796" velocity="6.283184"/>
    <origin rpy="0 0 0" xyz="-0.0245 0 -0.158"/>
    <parent link="link_13"/>
    <child link="link_14"/>
    <dynamics damping="0.1" friction="0.1"/>
  </joint>
  <transmission name="trans_dualarm_joint14">
    <type>transmission_interface/SimpleTransmission</type>
    <joint name="dualarm_joint14">
      <hardwareInterface>hardware_interface/EffortJointInterface</hardwareInterface>
    </joint>
    <actuator name="motor_dualarm_joint14">
      <hardwareInterface>hardware_interface/EffortJointInterface</hardwareInterface>
      <mechanicalReduction>1</mechanicalReduction>
    </actuator>
  </transmission>
  <link name="link_14">
    <inertial>
      <mass value="1.86"/>
      <origin rpy="0 0 0" xyz="0.02219 -0.00137 -0.09649"/>
      <inertia ixx="0.0049321265" ixy="8.082944e-05" ixz="-0.00035330192" iyy="0.00407685409" iyz="-0.00035589762" izz="0.00225524843"/>
    </inertial>
    <visual>
      <origin rpy="0 0 0" xyz="0 0 0"/>
      <geometry>
        <mesh filename="package://dualarm_description/meshes/dualarm1/link7.STL" scale="0.001 0.001 0.001"/>
      </geometry>
    </visual>
  </link>
  <joint name="dualarm_joint15" type="revolute">
    <axis xyz="0 0 1"/>
    <limit effort="300" lower="-3.141592" upper="3.141592" velocity="3.141592"/>
    <origin rpy="0 0 0" xyz="0.0245 0 -0.155"/>
    <parent link="link_14"/>
    <child link="link_15"/>
    <dynamics damping="0.1" friction="0.1"/>
  </joint>
  <transmission name="trans_dualarm_joint15">
    <type>transmission_interface/SimpleTransmission</type>
    <joint name="dualarm_joint15">
      <hardwareInterface>hardware_interface/EffortJointInterface</hardwareInterface>
    </joint>
    <actuator name="motor_dualarm_joint15">
      <hardwareInterface>hardware_interface/EffortJointInterface</hardwareInterface>
      <mechanicalReduction>1</mechanicalReduction>
    </actuator>
  </transmission>
  <link name="link_15">
    <inertial>
      <mass value="2.1946"/>
      <origin rpy="0 0 0" xyz="0.00173 0.00014 -0.13722"/>
      <inertia ixx="0.06463882947" ixy="-0.00018258555" ixz="-0.00113241818" iyy="0.06665901777" iyz="0.0020232708" izz="0.0045668994"/>
    </inertial>
    <visual>
      <origin rpy="0 0 0" xyz="0 0 0"/>
      <geometry>
        <mesh filename="package://dualarm_description/meshes/dualarm1/Wrist.STL" scale="0.001 0.001 0.001"/>
      </geometry>
    </visual>
  </link>
  <joint name="dualarm_joint16" type="revolute">
    <axis xyz="1 0 0"/>
    <limit effort="300" lower="-3.141592" upper="3.141592" velocity="3.141592"/>
    <origin rpy="0 0 0" xyz="0 0 -0.0755"/>
    <parent link="link_15"/>
    <child link="link_L_hand"/>
    <dynamics damping="0.1" friction="0.1"/>
  </joint>
  <transmission name="trans_dualarm_joint16">
    <type>transmission_interface/SimpleTransmission</type>
    <joint name="dualarm_joint16">
      <hardwareInterface>hardware_interface/EffortJointInterface</hardwareInterface>
    </joint>
    <actuator name="motor_dualarm_joint16">
      <hardwareInterface>hardware_interface/EffortJointInterface</hardwareInterface>
      <mechanicalReduction>1</mechanicalReduction>
    </actuator>
  </transmission>
  <link name="link_L_hand">
    <inertial>
      <mass value="1.29"/>
      <origin rpy="0 0 0" xyz="0 0 0"/>
      <inertia ixx="0.00753488339" ixy="0.0" ixz="0.0" iyy="0.00948557812" iyz="-0.00065921999" izz="0.02588099664"/>
    </inertial>
    <visual>
      <origin rpy="0 0 0" xyz="0 0 0"/>
      <geometry>
        <mesh filename="package://dualarm_description/meshes/dualarm1/hand_adapter_L.STL" scale="0.001 0.001 0.001"/>
      </geometry>
    </visual>
  </link>
  <joint name="dualarm_L_end" type="fixed">
    <origin rpy="0 0 0" xyz="0 0 -0.122"/>
    <parent link="link_L_hand"/>
    <child link="dualarm_L_end_frame"/>
  </joint>
  <link name="dualarm_L_end_frame"/>
</robot>

