<?xml version="1.0" ?>
<!-- =================================================================================== -->
<!-- |    This document was autogenerated by xacro from dual_arm.xacro                 | -->
<!-- |    EDITING THIS FILE BY HAND IS NOT RECOMMENDED                                 | -->
<!-- =================================================================================== -->
<robot name="dualarm">
  <!-- ros_control plugin -->
  <gazebo>
    <plugin filename="libgazebo_ros_control.so" name="gazebo_ros_control">
      <robotNamespace>/dualarm</robotNamespace>
      <robotSimType>gazebo_ros_control/DefaultRobotHWSim</robotSimType>
      <controlPeriod>0.001</controlPeriod>
    </plugin>
  </gazebo>
  <!-- Base parts -->
  <link name="world"/>
  <joint name="base_joint" type="fixed">
    <origin rpy="0 0 0" xyz="0 0 0"/>
    <parent link="world"/>
    <child link="dual_arm_base_link"/>
  </joint>
  <link name="dual_arm_base_link"/>
  <joint name="dual_arm_base_joint" type="fixed">
    <origin rpy="0 0 0" xyz="0 0 0.3"/>
    <parent link="dual_arm_base_link"/>
    <child link="robot_base_link"/>
  </joint>
  <link name="robot_base_link">
    <inertial>
      <mass value="10.0"/>
      <origin rpy="0 0 0" xyz="0 0 0.15"/>
      <inertia ixx="0.0" ixy="0.0" ixz="0.0" iyy="0.0" iyz="0.0" izz="0.0"/>
    </inertial>
    <visual>
      <origin rpy="0 0 0" xyz="0 0 0"/>
      <geometry>
        <mesh filename="package://dualarm_description/meshes/stl/base.STL" scale="0.001 0.001 0.001"/>
      </geometry>
    </visual>
  </link>
  <!-- waist part -->
  <joint name="dualarm_joint1" type="revolute">
    <axis xyz="0 0 -1"/>
    <limit effort="300" lower="-3.141592" upper="3.141592" velocity="6.283184"/>
    <origin rpy="0 0 0" xyz="0 0 0.3031"/>
    <parent link="robot_base_link"/>
    <child link="link_01"/>
    <dynamics damping="0.1" friction="0.1"/>
  </joint>
  <transmission name="trans_dualarm_joint1">
    <type>transmission_interface/SimpleTransmission</type>
    <joint name="dualarm_joint1">
      <hardwareInterface>hardware_interface/EffortJointInterface</hardwareInterface>
    </joint>
    <actuator name="motor_dualarm_joint1">
      <hardwareInterface>hardware_interface/EffortJointInterface</hardwareInterface>
      <mechanicalReduction>1</mechanicalReduction>
    </actuator>
  </transmission>
  <link name="link_01">
    <inertial>
      <mass value="6.61"/>
      <origin rpy="0 0 0" xyz="-0.0001211 -0.0015722 0.1519998"/>
      <inertia ixx="0.0522" ixy="-0.0001" ixz="0.0" iyy="0.0395" iyz="0.0003" izz="0.0314"/>
    </inertial>
    <visual>
      <origin rpy="0 0 0" xyz="0 0 0"/>
      <geometry>
        <mesh filename="package://dualarm_description/meshes/stl/waist1.STL" scale="0.001 0.001 0.001"/>
      </geometry>
    </visual>
  </link>
  <joint name="dualarm_joint2" type="revolute">
    <axis xyz="0 -1 0"/>
    <limit effort="300" lower="-3.141592" upper="3.141592" velocity="6.283184"/>
    <origin rpy="0 0 0" xyz="0 0 0.1969"/>
    <parent link="link_01"/>
    <child link="link_02"/>
    <dynamics damping="0.1" friction="0.1"/>
  </joint>
  <transmission name="trans_dualarm_joint2">
    <type>transmission_interface/SimpleTransmission</type>
    <joint name="dualarm_joint2">
      <hardwareInterface>hardware_interface/EffortJointInterface</hardwareInterface>
    </joint>
    <actuator name="motor_dualarm_joint2">
      <hardwareInterface>hardware_interface/EffortJointInterface</hardwareInterface>
      <mechanicalReduction>1</mechanicalReduction>
    </actuator>
  </transmission>
  <link name="link_02">
    <inertial>
      <mass value="8.2662"/>
      <origin rpy="0 0 0" xyz="0.00597 0.0059226 0.1235"/>
      <inertia ixx="0.1164" ixy="-0.0003" ixz="0.0021" iyy="0.0422" iyz="-0.0034" izz="0.0948"/>
    </inertial>
    <visual>
      <origin rpy="0 0 0" xyz="0 0 0"/>
      <geometry>
        <mesh filename="package://dualarm_description/meshes/stl/waist2.STL" scale="0.001 0.001 0.001"/>
      </geometry>
    </visual>
  </link>
  <!--
	right_arm part
	-->
  <joint name="dualarm_joint3" type="revolute">
    <axis xyz="0 0 -1"/>
    <limit effort="300" lower="-3.141592" upper="3.141592" velocity="6.283184"/>
    <origin rpy="0 0 0" xyz="0 -0.125 0.18565"/>
    <parent link="link_02"/>
    <child link="link_03"/>
    <dynamics damping="0.1" friction="0.1"/>
  </joint>
  <transmission name="trans_dualarm_joint3">
    <type>transmission_interface/SimpleTransmission</type>
    <joint name="dualarm_joint3">
      <hardwareInterface>hardware_interface/EffortJointInterface</hardwareInterface>
    </joint>
    <actuator name="motor_dualarm_joint3">
      <hardwareInterface>hardware_interface/EffortJointInterface</hardwareInterface>
      <mechanicalReduction>1</mechanicalReduction>
    </actuator>
  </transmission>
  <link name="link_03">
    <inertial>
      <mass value="2.8163"/>
      <origin rpy="0 0 0" xyz="-0.0007018 -0.0179392 0.0955618"/>
      <inertia ixx="0.0077" ixy="0.0001" ixz="0.0" iyy="0.0065" iyz="-0.0008" izz="0.005"/>
    </inertial>
    <visual>
      <origin rpy="0 0 0" xyz="0 0 0"/>
      <geometry>
        <mesh filename="package://dualarm_description/meshes/stl/r1.STL" scale="0.001 0.001 0.001"/>
      </geometry>
    </visual>
  </link>
  <joint name="dualarm_joint4" type="revolute">
    <axis xyz="0 1 0"/>
    <limit effort="300" lower="-3.141592" upper="3.141592" velocity="6.283184"/>
    <origin rpy="0 0 0" xyz="0 -0.05265 0.11435"/>
    <parent link="link_03"/>
    <child link="link_04"/>
    <dynamics damping="0.1" friction="0.1"/>
  </joint>
  <transmission name="trans_dualarm_joint4">
    <type>transmission_interface/SimpleTransmission</type>
    <joint name="dualarm_joint4">
      <hardwareInterface>hardware_interface/EffortJointInterface</hardwareInterface>
    </joint>
    <actuator name="motor_dualarm_joint4">
      <hardwareInterface>hardware_interface/EffortJointInterface</hardwareInterface>
      <mechanicalReduction>1</mechanicalReduction>
    </actuator>
  </transmission>
  <link name="link_04">
    <inertial>
      <mass value="3.213"/>
      <origin rpy="0 0 0" xyz="-0.00021 -0.1153861 0.00077"/>
      <inertia ixx="0.0108" ixy="0.0002" ixz="-0.0001" iyy="0.0055" iyz="-0.0001" izz="0.0116"/>
    </inertial>
    <visual>
      <origin rpy="0 0 0" xyz="0 0 0"/>
      <geometry>
        <mesh filename="package://dualarm_description/meshes/stl/r2.STL" scale="0.001 0.001 0.001"/>
      </geometry>
    </visual>
  </link>
  <joint name="dualarm_joint5" type="revolute">
    <axis xyz="1 0 0"/>
    <limit effort="300" lower="-3.141592" upper="3.141592" velocity="6.283184"/>
    <origin rpy="0 0 0" xyz="0 -0.14735 0"/>
    <parent link="link_04"/>
    <child link="link_05"/>
    <dynamics damping="0.1" friction="0.1"/>
  </joint>
  <transmission name="trans_dualarm_joint5">
    <type>transmission_interface/SimpleTransmission</type>
    <joint name="dualarm_joint5">
      <hardwareInterface>hardware_interface/EffortJointInterface</hardwareInterface>
    </joint>
    <actuator name="motor_dualarm_joint5">
      <hardwareInterface>hardware_interface/EffortJointInterface</hardwareInterface>
      <mechanicalReduction>1</mechanicalReduction>
    </actuator>
  </transmission>
  <link name="link_05">
    <inertial>
      <mass value="2.4856"/>
      <origin rpy="0 0 0" xyz="-0.0025431 -0.0001796 -0.1503879"/>
      <inertia ixx="0.0138" ixy="0.0" ixz="-0.0011" iyy="0.0153" iyz="0.0" izz="0.0037"/>
    </inertial>
    <visual>
      <origin rpy="0 0 0" xyz="0 0 0"/>
      <geometry>
        <mesh filename="package://dualarm_description/meshes/stl/r3.STL" scale="0.001 0.001 0.001"/>
      </geometry>
    </visual>
  </link>
  <joint name="dualarm_joint6" type="revolute">
    <axis xyz="0 0 1"/>
    <limit effort="300" lower="-3.141592" upper="3.141592" velocity="6.283184"/>
    <origin rpy="0 0 0" xyz="0 0 -0.21425"/>
    <parent link="link_05"/>
    <child link="link_06"/>
    <dynamics damping="0.1" friction="0.1"/>
  </joint>
  <transmission name="trans_dualarm_joint6">
    <type>transmission_interface/SimpleTransmission</type>
    <joint name="dualarm_joint6">
      <hardwareInterface>hardware_interface/EffortJointInterface</hardwareInterface>
    </joint>
    <actuator name="motor_dualarm_joint6">
      <hardwareInterface>hardware_interface/EffortJointInterface</hardwareInterface>
      <mechanicalReduction>1</mechanicalReduction>
    </actuator>
  </transmission>
  <link name="link_06">
    <inertial>
      <mass value="2.1204"/>
      <origin rpy="0 0 0" xyz="-0.0191 0.0026 -0.1364"/>
      <inertia ixx="0.0105" ixy="0.0" ixz="0.0011" iyy="0.0093" iyz="-0.0003" izz="0.0031"/>
    </inertial>
    <visual>
      <origin rpy="0 0 0" xyz="0 0 0"/>
      <geometry>
        <mesh filename="package://dualarm_description/meshes/stl/r4.STL" scale="0.001 0.001 0.001"/>
      </geometry>
    </visual>
  </link>
  <joint name="dualarm_joint7" type="revolute">
    <axis xyz="0 1 0"/>
    <limit effort="300" lower="-3.141592" upper="3.141592" velocity="6.283184"/>
    <origin rpy="0 0 0" xyz="-0.0245 0 -0.18575"/>
    <parent link="link_06"/>
    <child link="link_07"/>
    <dynamics damping="0.1" friction="0.1"/>
  </joint>
  <transmission name="trans_dualarm_joint7">
    <type>transmission_interface/SimpleTransmission</type>
    <joint name="dualarm_joint7">
      <hardwareInterface>hardware_interface/EffortJointInterface</hardwareInterface>
    </joint>
    <actuator name="motor_dualarm_joint7">
      <hardwareInterface>hardware_interface/EffortJointInterface</hardwareInterface>
      <mechanicalReduction>1</mechanicalReduction>
    </actuator>
  </transmission>
  <link name="link_07">
    <inertial>
      <mass value="1.8777"/>
      <origin rpy="0 0 0" xyz="-0.0023 0.0022 -0.0965"/>
      <inertia ixx="0.0051" ixy="-0.0001" ixz="0.0001" iyy="0.0043" iyz="0.0003" izz="0.0023"/>
    </inertial>
    <visual>
      <origin rpy="0 0 0" xyz="0 0 0"/>
      <geometry>
        <mesh filename="package://dualarm_description/meshes/stl/r5.STL" scale="0.001 0.001 0.001"/>
      </geometry>
    </visual>
  </link>
  <joint name="dualarm_joint8" type="revolute">
    <axis xyz="0 0 1"/>
    <limit effort="300" lower="-3.141592" upper="3.141592" velocity="6.283184"/>
    <origin rpy="0 0 0" xyz="0.0245 0 -0.14"/>
    <parent link="link_07"/>
    <child link="link_08"/>
    <dynamics damping="0.1" friction="0.1"/>
  </joint>
  <transmission name="trans_dualarm_joint8">
    <type>transmission_interface/SimpleTransmission</type>
    <joint name="dualarm_joint8">
      <hardwareInterface>hardware_interface/EffortJointInterface</hardwareInterface>
    </joint>
    <actuator name="motor_dualarm_joint8">
      <hardwareInterface>hardware_interface/EffortJointInterface</hardwareInterface>
      <mechanicalReduction>1</mechanicalReduction>
    </actuator>
  </transmission>
  <link name="link_08">
    <inertial>
      <mass value="2.6999"/>
      <origin rpy="0 0 0" xyz="0.0036 -0.0004 -0.0746"/>
      <inertia ixx="0.0037" ixy="0.0" ixz="-0.0002" iyy="0.0049" iyz="0.0" izz="0.0031"/>
    </inertial>
    <visual>
      <origin rpy="0 0 0" xyz="0 0 0"/>
      <geometry>
        <mesh filename="package://dualarm_description/meshes/stl/r6.STL" scale="0.001 0.001 0.001"/>
      </geometry>
    </visual>
  </link>
  <joint name="dualarm_joint9" type="revolute">
    <axis xyz="1 0 0"/>
    <limit effort="300" lower="-3.141592" upper="3.141592" velocity="6.283184"/>
    <origin rpy="0 0 0" xyz="0 0 -0.091"/>
    <parent link="link_08"/>
    <child link="link_R_hand"/>
    <dynamics damping="0.1" friction="0.1"/>
  </joint>
  <transmission name="trans_dualarm_joint9">
    <type>transmission_interface/SimpleTransmission</type>
    <joint name="dualarm_joint9">
      <hardwareInterface>hardware_interface/EffortJointInterface</hardwareInterface>
    </joint>
    <actuator name="motor_dualarm_joint9">
      <hardwareInterface>hardware_interface/EffortJointInterface</hardwareInterface>
      <mechanicalReduction>1</mechanicalReduction>
    </actuator>
  </transmission>
  <link name="link_R_hand">
    <inertial>
      <mass value="1.6338"/>
      <origin rpy="0 0 0" xyz="0.0099 0.0087 -0.126"/>
      <inertia ixx="0.0108" ixy="0.0005" ixz="0.0003" iyy="0.0125" iyz="-0.0004" izz="0.0033"/>
    </inertial>
    <visual>
      <origin rpy="0 0 0" xyz="0 0 0"/>
      <geometry>
        <mesh filename="package://dualarm_description/meshes/stl/r7.STL" scale="0.001 0.001 0.001"/>
      </geometry>
    </visual>
  </link>
  <joint name="dualarm_R_end" type="fixed">
    <origin rpy="0 0 0" xyz="0 0 -0.04681"/>
    <parent link="link_R_hand"/>
    <child link="dualarm_R_end_frame"/>
  </joint>
  <link name="dualarm_R_end_frame"/>
  <!-- left_arm part-->
  <joint name="dualarm_joint10" type="revolute">
    <axis xyz="0 0 -1"/>
    <limit effort="300" lower="-1.570796" upper="1.570796" velocity="6.283184"/>
    <origin rpy="0 0 0" xyz="0 0.125 0.18565"/>
    <parent link="link_02"/>
    <child link="link_10"/>
    <dynamics damping="0.1" friction="0.1"/>
  </joint>
  <transmission name="trans_dualarm_joint10">
    <type>transmission_interface/SimpleTransmission</type>
    <joint name="dualarm_joint10">
      <hardwareInterface>hardware_interface/EffortJointInterface</hardwareInterface>
    </joint>
    <actuator name="motor_dualarm_joint10">
      <hardwareInterface>hardware_interface/EffortJointInterface</hardwareInterface>
      <mechanicalReduction>1</mechanicalReduction>
    </actuator>
  </transmission>
  <link name="link_10">
    <inertial>
      <mass value="2.8163"/>
      <origin rpy="0 0 0" xyz="-0.0009 0.0179 0.0957"/>
      <inertia ixx="0.0077" ixy="-0.0001" ixz="0.0" iyy="0.0064" iyz="0.0008" izz="0.0051"/>
    </inertial>
    <visual>
      <origin rpy="0 0 0" xyz="0 0 0"/>
      <geometry>
        <mesh filename="package://dualarm_description/meshes/stl/l1.STL" scale="0.001 0.001 0.001"/>
      </geometry>
    </visual>
  </link>
  <joint name="dualarm_joint11" type="revolute">
    <axis xyz="0 -1 0"/>
    <limit effort="300" lower="-1.570796" upper="1.570796" velocity="6.283184"/>
    <origin rpy="0 0 0" xyz="0 0.05265 0.11435"/>
    <parent link="link_10"/>
    <child link="link_11"/>
    <dynamics damping="0.1" friction="0.1"/>
  </joint>
  <transmission name="trans_dualarm_joint11">
    <type>transmission_interface/SimpleTransmission</type>
    <joint name="dualarm_joint11">
      <hardwareInterface>hardware_interface/EffortJointInterface</hardwareInterface>
    </joint>
    <actuator name="motor_dualarm_joint11">
      <hardwareInterface>hardware_interface/EffortJointInterface</hardwareInterface>
      <mechanicalReduction>1</mechanicalReduction>
    </actuator>
  </transmission>
  <link name="link_11">
    <inertial>
      <mass value="3.213"/>
      <origin rpy="0 0 0" xyz="0.0009 0.1131 0.0005"/>
      <inertia ixx="0.0106" ixy="-0.0001" ixz="-0.0001" iyy="0.0058" iyz="0.0001" izz="0.012"/>
    </inertial>
    <visual>
      <origin rpy="0 0 0" xyz="0 0 0"/>
      <geometry>
        <mesh filename="package://dualarm_description/meshes/stl/l2.STL" scale="0.001 0.001 0.001"/>
      </geometry>
    </visual>
  </link>
  <joint name="dualarm_joint12" type="revolute">
    <axis xyz="1 0 0"/>
    <limit effort="200" lower="-0.785398" upper="1.570796" velocity="6.283184"/>
    <origin rpy="0 0 0" xyz="0 0.14735 0"/>
    <parent link="link_11"/>
    <child link="link_12"/>
    <dynamics damping="0.1" friction="0.1"/>
  </joint>
  <transmission name="trans_dualarm_joint12">
    <type>transmission_interface/SimpleTransmission</type>
    <joint name="dualarm_joint12">
      <hardwareInterface>hardware_interface/EffortJointInterface</hardwareInterface>
    </joint>
    <actuator name="motor_dualarm_joint12">
      <hardwareInterface>hardware_interface/EffortJointInterface</hardwareInterface>
      <mechanicalReduction>1</mechanicalReduction>
    </actuator>
  </transmission>
  <link name="link_12">
    <inertial>
      <mass value="2.4856"/>
      <origin rpy="0 0 0" xyz="-0.0024 0.0002 -0.1504"/>
      <inertia ixx="0.0138" ixy="0.0" ixz="-0.0011" iyy="0.0153" iyz="0.0" izz="0.0037"/>
    </inertial>
    <visual>
      <origin rpy="0 0 0" xyz="0 0 0"/>
      <geometry>
        <mesh filename="package://dualarm_description/meshes/stl/l3.STL" scale="0.001 0.001 0.001"/>
      </geometry>
    </visual>
  </link>
  <joint name="dualarm_joint13" type="revolute">
    <axis xyz="0 0 1"/>
    <limit effort="200" lower="-1.570796" upper="1.570796" velocity="6.283184"/>
    <origin rpy="0 0 0" xyz="0 0 -0.21425"/>
    <parent link="link_12"/>
    <child link="link_13"/>
    <dynamics damping="0.1" friction="0.1"/>
  </joint>
  <transmission name="trans_dualarm_joint13">
    <type>transmission_interface/SimpleTransmission</type>
    <joint name="dualarm_joint13">
      <hardwareInterface>hardware_interface/EffortJointInterface</hardwareInterface>
    </joint>
    <actuator name="motor_dualarm_joint13">
      <hardwareInterface>hardware_interface/EffortJointInterface</hardwareInterface>
      <mechanicalReduction>1</mechanicalReduction>
    </actuator>
  </transmission>
  <link name="link_13">
    <inertial>
      <mass value="2.1204"/>
      <origin rpy="0 0 0" xyz="-0.0189 -0.0027 -0.136"/>
      <inertia ixx="0.0105" ixy="0.0001" ixz="0.0011" iyy="0.0094" iyz="0.0002" izz="0.0031"/>
    </inertial>
    <visual>
      <origin rpy="0 0 0" xyz="0 0 0"/>
      <geometry>
        <mesh filename="package://dualarm_description/meshes/stl/l4.STL" scale="0.001 0.001 0.001"/>
      </geometry>
    </visual>
  </link>
  <joint name="dualarm_joint14" type="revolute">
    <axis xyz="0 -1 0"/>
    <limit effort="300" lower="-0.785398" upper="1.570796" velocity="6.283184"/>
    <origin rpy="0 0 0" xyz="-0.0245 0 -0.18575"/>
    <parent link="link_13"/>
    <child link="link_14"/>
    <dynamics damping="0.1" friction="0.1"/>
  </joint>
  <transmission name="trans_dualarm_joint14">
    <type>transmission_interface/SimpleTransmission</type>
    <joint name="dualarm_joint14">
      <hardwareInterface>hardware_interface/EffortJointInterface</hardwareInterface>
    </joint>
    <actuator name="motor_dualarm_joint14">
      <hardwareInterface>hardware_interface/EffortJointInterface</hardwareInterface>
      <mechanicalReduction>1</mechanicalReduction>
    </actuator>
  </transmission>
  <link name="link_14">
    <inertial>
      <mass value="1.8777"/>
      <origin rpy="0 0 0" xyz="-0.0023 -0.0014 -0.0965"/>
      <inertia ixx="0.0051" ixy="0.0001" ixz="-0.0004" iyy="0.0043" iyz="-0.0004" izz="0.0024"/>
    </inertial>
    <visual>
      <origin rpy="0 0 0" xyz="0 0 0"/>
      <geometry>
        <mesh filename="package://dualarm_description/meshes/stl/l5.STL" scale="0.001 0.001 0.001"/>
      </geometry>
    </visual>
  </link>
  <joint name="dualarm_joint15" type="revolute">
    <axis xyz="0 0 1"/>
    <limit effort="300" lower="-3.141592" upper="3.141592" velocity="3.141592"/>
    <origin rpy="0 0 0" xyz="0.0245 0 -0.14"/>
    <parent link="link_14"/>
    <child link="link_15"/>
    <dynamics damping="0.1" friction="0.1"/>
  </joint>
  <transmission name="trans_dualarm_joint15">
    <type>transmission_interface/SimpleTransmission</type>
    <joint name="dualarm_joint15">
      <hardwareInterface>hardware_interface/EffortJointInterface</hardwareInterface>
    </joint>
    <actuator name="motor_dualarm_joint15">
      <hardwareInterface>hardware_interface/EffortJointInterface</hardwareInterface>
      <mechanicalReduction>1</mechanicalReduction>
    </actuator>
  </transmission>
  <link name="link_15">
    <inertial>
      <mass value="2.6999"/>
      <origin rpy="0 0 0" xyz="0.0039 -0.0002 -0.08"/>
      <inertia ixx="0.0031" ixy="0.0" ixz="-0.0001" iyy="0.0044" iyz="0.0" izz="0.0032"/>
    </inertial>
    <visual>
      <origin rpy="0 0 0" xyz="0 0 0"/>
      <geometry>
        <mesh filename="package://dualarm_description/meshes/stl/l6.STL" scale="0.001 0.001 0.001"/>
      </geometry>
    </visual>
  </link>
  <joint name="dualarm_joint16" type="revolute">
    <axis xyz="1 0 0"/>
    <limit effort="300" lower="-3.141592" upper="3.141592" velocity="3.141592"/>
    <origin rpy="0 0 0" xyz="0 0 -0.091"/>
    <parent link="link_15"/>
    <child link="link_L_hand"/>
    <dynamics damping="0.1" friction="0.1"/>
  </joint>
  <transmission name="trans_dualarm_joint16">
    <type>transmission_interface/SimpleTransmission</type>
    <joint name="dualarm_joint16">
      <hardwareInterface>hardware_interface/EffortJointInterface</hardwareInterface>
    </joint>
    <actuator name="motor_dualarm_joint16">
      <hardwareInterface>hardware_interface/EffortJointInterface</hardwareInterface>
      <mechanicalReduction>1</mechanicalReduction>
    </actuator>
  </transmission>
  <link name="link_L_hand">
    <inertial>
      <mass value="1.5"/>
      <origin rpy="0 0 0" xyz="0.0099 -0.0087 -0.126"/>
      <inertia ixx="0.0017" ixy="0.0" ixz="0.0004" iyy="0.0031" iyz="0.0" izz="0.0029"/>
    </inertial>
    <visual>
      <origin rpy="0 0 0" xyz="0 0 0"/>
      <geometry>
        <mesh filename="package://dualarm_description/meshes/dualarm1/hand_adapter_L.STL" scale="0.001 0.001 0.001"/>
      </geometry>
    </visual>
  </link>
  <joint name="dualarm_L_end" type="fixed">
    <origin rpy="0 0 0" xyz="0 0 -0.04681"/>
    <parent link="link_L_hand"/>
    <child link="dualarm_L_end_frame"/>
  </joint>
  <link name="dualarm_L_end_frame"/>
</robot>

