<?xml version="1.0" ?>
<!-- =================================================================================== -->
<!-- |    This document was autogenerated by xacro from dual_arm.xacro                 | -->
<!-- |    EDITING THIS FILE BY HAND IS NOT RECOMMENDED                                 | -->
<!-- =================================================================================== -->
<robot name="dualarm" xmlns:xacro="http://www.ros.org/wiki/xacro">
  <!--waist-->
  <!-- Base parts -->
  <link name="world"/>
  <joint name="base_joint" type="fixed">
    <parent link="world"/>
    <child link="base_link"/>
  </joint>
  <link name="base_link">
    <inertial>
      <mass value="10.0"/>
      <origin rpy="0 0 0" xyz="0 0 0.176"/>
      <inertia ixx="0.0" ixy="0.0" ixz="0.0" iyy="0.0" iyz="0.0" izz="0.0"/>
    </inertial>
    <collision>
      <origin rpy="0 0 0" xyz="0 0 0.176"/>
      <geometry>
      <cylinder length="0.352" radius="0.15"/>
      </geometry>
    </collision>
    <visual>
      <origin rpy="0 0 0" xyz="0 0 0"/>
      <geometry>
        <!--<cylinder length="0.352" radius="0.15"/>-->
        <mesh filename="package://dualarm_description/meshes/dualarm/base.STL" scale="0.001 0.001 0.001"/>
      </geometry>
    </visual>
  </link>
  <joint name="base_link_link_01" type="revolute">
    <axis xyz="0 0 1"/>
    <limit effort="100" lower="-1.5708" upper="1.5708" velocity="1"/>
    <origin rpy="0 0 0" xyz="0 0 0.352"/>
    <parent link="base_link"/>
    <child link="link_01"/>
  </joint>
  <transmission name="trans_base_link_link_01">
    <type>transmission_interface/SimpleTransmission</type>
    <joint name="base_link_link_01">
      <hardwareInterface>hardware_interface/EffortJointInterface</hardwareInterface>
    </joint>
    <actuator name="motor_base_link_link_01">
      <hardwareInterface>hardware_interface/EffortJointInterface</hardwareInterface>
      <mechanicalReduction>101</mechanicalReduction>
    </actuator>
  </transmission>
  <link name="link_01">
    <inertial>
      <mass value="6.6152"/>
      <origin rpy="0 0 0" xyz="0 0 0.1110776"/>
      <inertia ixx="0.0463" ixy="0.0" ixz="0.0" iyy="-0.0367" iyz="0.0026849" izz="0.0271"/>
    </inertial>
    <collision>
      <origin rpy="-1.57 0 0" xyz="0 0 0.1110776"/>
      <geometry>
        <cylinder length="0.148" radius="0.06"/>
      </geometry>
    </collision>
    <visual>
      <origin rpy="0 0 0" xyz="0 0 0.150"/>
      <geometry>
        <!--<cylinder length="0.148" radius="0.06"/>-->
        <mesh filename="package://dualarm_description/meshes/dualarm/waist_1.STL" scale="0.001 0.001 0.001" />
      </geometry>
    </visual>
  </link>
  <joint name="link_01_link_02" type="revolute">
    <axis xyz="0 1 0"/>
    <limit effort="100" lower="-0.2618" upper="1.22173" velocity="1"/>
    <origin rpy="0 0 0" xyz="0 0 0.148"/>
    <parent link="link_01"/>
    <child link="link_02"/>
  </joint>
  <transmission name="trans_link_01_link_02">
    <type>transmission_interface/SimpleTransmission</type>
    <joint name="link_01_link_02">
      <hardwareInterface>hardware_interface/EffortJointInterface</hardwareInterface>
    </joint>
    <actuator name="motor_link_01_link_02">
      <hardwareInterface>hardware_interface/EffortJointInterface</hardwareInterface>
      <mechanicalReduction>101</mechanicalReduction>
    </actuator>
  </transmission>
  <link name="link_02">
    <inertial>
      <mass value="8.2662"/>
      <origin rpy="0 0 0" xyz="0 0 0.1436171"/>
      <inertia ixx="0.1408" ixy="0.0" ixz="0.0007" iyy="0.05" iyz="0.003643" izz="0.108"/>
    </inertial>
    <collision>
      <origin rpy="0 0 0" xyz="0 0 0.1436171"/>
      <geometry>
        <cylinder length="0.217" radius="0.2"/>
      </geometry>
    </collision>
    <visual>
      <origin rpy="0 0 0" xyz="0 0 0"/>
      <geometry>
        <!--<cylinder length="0.217" radius="0.2"/>-->
        <mesh filename="package://dualarm_description/meshes/dualarm/waist_2.STL" scale="0.001 0.001 0.001" />
      </geometry>
    </visual>
  </link>

  <!-- right_arm part -->
  <link name="link_03">
    <inertial>
      <mass value="2.8163"/>
      <origin rpy="0 0 0" xyz="0.0002952 0.0341703 0.076461"/>
      <inertia ixx="0.0057" ixy="0.0" ixz="0.0" iyy="0.0055" iyz="-0.0005" izz="0.0044"/>
    </inertial>
    <collision>
      <origin rpy="-1.57 0 0" xyz="0.0002952 0.0341703 0.076461"/>
      <geometry>
        <cylinder length="0.083" radius="0.04"/>
      </geometry>
    </collision>
    <visual>
      <origin rpy="0 0 0" xyz="0 0.08 0.083"/>
      <geometry>
        <!--<cylinder length="0.083" radius="0.04"/>-->
        <mesh filename="package://dualarm_description/meshes/dualarm/r_arm1.STL" scale="0.001 0.001 0.001" />
      </geometry>
    </visual>
  </link>
  <joint name="link_02_link_03" type="revolute">
    <axis xyz="0 0 1"/>
    <limit effort="100" lower="-1.5708" upper="0.5236" velocity="1"/>
    <origin rpy="0 0 0" xyz="0 0.125 0.217"/>
    <parent link="link_02"/>
    <child link="link_03"/>
  </joint>
  <transmission name="trans_link_02_link_03">
    <type>transmission_interface/SimpleTransmission</type>
    <joint name="link_02_link_03">
      <hardwareInterface>hardware_interface/EffortJointInterface</hardwareInterface>
    </joint>
    <actuator name="motor_link_02_link_03">
      <hardwareInterface>hardware_interface/EffortJointInterface</hardwareInterface>
      <mechanicalReduction>101</mechanicalReduction>
    </actuator>
  </transmission>
  <link name="link_04">
    <inertial>
      <mass value="3.213"/>
      <origin rpy="0 0 0" xyz="0.0112502 0.0950175 0"/>
      <inertia ixx="0.0088" ixy="-0.0115" ixz="0.0289" iyy="0.0049" iyz="-0.797" izz="0.0089"/>
    </inertial>
    <collision>
      <origin rpy="0 1.57 0" xyz="0.0112502 0.0950175 0"/>
      <geometry>
        <cylinder length="0.09" radius="0.04"/>
      </geometry>
    </collision>
    <visual>
      <origin rpy="0 0 0" xyz="0 0.11 0"/>
      <geometry>
        <!--<cylinder length="0.09" radius="0.04"/>-->
        <mesh filename="package://dualarm_description/meshes/dualarm/r_arm2.STL" scale="0.001 0.001 0.001" />
      </geometry>
    </visual>
  </link>
  <joint name="link_03_link_04" type="revolute">
    <axis xyz="0 1 0"/>
    <limit effort="100" lower="-1.5708" upper="0.7854" velocity="1"/>
    <origin rpy="0 0 0" xyz="0 0.09 0.083"/>
    <parent link="link_03"/>
    <child link="link_04"/>
  </joint>
  <transmission name="trans_link_03_link_04">
    <type>transmission_interface/SimpleTransmission</type>
    <joint name="link_03_link_04">
      <hardwareInterface>hardware_interface/EffortJointInterface</hardwareInterface>
    </joint>
    <actuator name="motor_link_03_link_04">
      <hardwareInterface>hardware_interface/EffortJointInterface</hardwareInterface>
      <mechanicalReduction>101</mechanicalReduction>
    </actuator>
  </transmission>
  <link name="link_05">
    <inertial>
      <mass value="2.4856"/>
      <origin rpy="0 0 0" xyz="0.0015675 0.0003615 -0.1633768"/>
      <inertia ixx="0.0103" ixy="0.0" ixz="0.0007" iyy="0.0112" iyz="0.0007" izz="0.003"/>
    </inertial>
    <collision>
      <origin rpy="3.14 0 0" xyz="0.0015675 0.0003615 -0.1633768"/>
      <geometry>
        <cylinder length="0.242" radius="0.05"/>
      </geometry>
    </collision>
    <visual>
      <origin rpy="0 0 0" xyz="0 0 -0.242"/>
      <geometry>
        <!--<cylinder length="0.242" radius="0.05"/>-->
        <mesh filename="package://dualarm_description/meshes/dualarm/r_arm3.STL" scale="0.001 0.001 0.001" />
      </geometry>
    </visual>
  </link>
  <joint name="link_04_link_05" type="revolute">
    <axis xyz="-1 0 0"/>
    <limit effort="100" lower="-1.5708" upper="0.349" velocity="1"/>
    <origin rpy="0 0 0" xyz="0 0.11 0"/>
    <parent link="link_04"/>
    <child link="link_05"/>
  </joint>
  <transmission name="trans_link_04_link_05">
    <type>transmission_interface/SimpleTransmission</type>
    <joint name="link_04_link_05">
      <hardwareInterface>hardware_interface/EffortJointInterface</hardwareInterface>
    </joint>
    <actuator name="motor_link_04_link_05">
      <hardwareInterface>hardware_interface/EffortJointInterface</hardwareInterface>
      <mechanicalReduction>101</mechanicalReduction>
    </actuator>
  </transmission>
  <link name="link_06">
    <inertial>
      <mass value="1.8893"/>
      <origin rpy="0 0 0" xyz="0.0219475 -0.008888 -0.1347982"/>
      <inertia ixx="0.0067" ixy="0.0" ixz="-0.0006" iyy="0.006" iyz="0.0" izz="0.0023"/>
    </inertial>
    <collision>
      <origin rpy="1.57 0 0" xyz="0.0219475 -0.008888 -0.1347982"/>
      <geometry>
        <cylinder length="0.158" radius="0.05"/>
      </geometry>
    </collision>
    <visual>
      <origin rpy="0 0 0" xyz="-0.00245 0.00175 -0.158"/>
      <geometry>
        <!--<cylinder length="0.158" radius="0.05"/>-->
        <mesh filename="package://dualarm_description/meshes/dualarm/r_arm4.STL" scale="0.001 0.001 0.001" />
      </geometry>
    </visual>
  </link>
  <joint name="link_05_link_06" type="revolute">
    <axis xyz="0 0 1"/>
    <limit effort="100" lower="-1.5708" upper="1.5708" velocity="0"/>
    <origin rpy="0 0 0" xyz="0 0 -0.242"/>
    <parent link="link_05"/>
    <child link="link_06"/>
  </joint>
  <transmission name="trans_link_05_link_06">
    <type>transmission_interface/SimpleTransmission</type>
    <joint name="link_05_link_06">
      <hardwareInterface>hardware_interface/EffortJointInterface</hardwareInterface>
    </joint>
    <actuator name="motor_link_05_link_06">
      <hardwareInterface>hardware_interface/EffortJointInterface</hardwareInterface>
      <mechanicalReduction>101</mechanicalReduction>
    </actuator>
  </transmission>
  <link name="link_07">
    <inertial>
      <mass value="1.8666"/>
      <origin rpy="0 0 0" xyz="0.0282566 -0.0026831 -0.1626786"/>
      <inertia ixx="0.0077" ixy="0.0" ixz="0.0003" iyy="0.007" iyz="0.0008" izz="0.0022"/>
    </inertial>
    <collision>
      <origin rpy="0 0 0" xyz="0.0282566 -0.0026831 -0.1626786"/>
      <geometry>
        <cylinder length="0.158" radius="0.05"/>
      </geometry>
    </collision>
    <visual>
      <origin rpy="0 0 0" xyz="0 0 0"/>
      <geometry>
        <!--<cylinder length="0.158" radius="0.05"/>-->
        <mesh filename="package://dualarm_description/meshes/dualarm/r_arm5.STL" scale="0.001 0.001 0.001" />
      </geometry>
    </visual>
  </link>
  <joint name="link_06_link_07" type="revolute">
    <axis xyz="0 -1 0"/>
    <limit effort="100" lower="0" upper="2.3562" velocity="1"/>
    <origin rpy="0 0 0" xyz="-0.0245 0.00175 -0.158"/>
    <parent link="link_06"/>
    <child link="link_07"/>
  </joint>
  <transmission name="trans_link_06_link_07">
    <type>transmission_interface/SimpleTransmission</type>
    <joint name="link_06_link_07">
      <hardwareInterface>hardware_interface/EffortJointInterface</hardwareInterface>
    </joint>
    <actuator name="motor_link_06_link_07">
      <hardwareInterface>hardware_interface/EffortJointInterface</hardwareInterface>
      <mechanicalReduction>101</mechanicalReduction>
    </actuator>
  </transmission>
  <link name="link_08">
    <inertial>
      <mass value="0.0646"/>
      <origin rpy="0 0 0" xyz="0 -0.0027174 -0.0051051"/>
      <inertia ixx="0.0" ixy="0.0" ixz="0.0" iyy="0.0" iyz="0.0" izz="0.0"/>
    </inertial>
    <collision>
      <origin rpy="0 0 0" xyz="0 -0.0027174 -0.0051051"/>
      <geometry>
        <cylinder length="0.01" radius="0.05"/>
      </geometry>
    </collision>
    <visual>
      <origin rpy="3.14 0 0" xyz="-0.032 0.034 0.085"/>
      <geometry>
        <!--<cylinder length="0.01" radius="0.05"/>-->
        <mesh filename="package://dualarm_description/meshes/dualarm/link6.STL" scale="0.001 0.001 0.001" />
      </geometry>
    </visual>
  </link>
  <joint name="link_07_link_08" type="revolute">
    <axis xyz="0 0 1"/>
    <limit effort="100" lower="-0.7854" upper="0.7854" velocity="0"/>
    <origin rpy="0 0 0" xyz="0.0245 -0.00175 -0.235"/>
    <parent link="link_07"/>
    <child link="link_08"/>
  </joint>
  <transmission name="trans_link_07_link_08">
    <type>transmission_interface/SimpleTransmission</type>
    <joint name="link_07_link_08">
      <hardwareInterface>hardware_interface/EffortJointInterface</hardwareInterface>
    </joint>
    <actuator name="motor_link_07_link_08">
      <hardwareInterface>hardware_interface/EffortJointInterface</hardwareInterface>
      <mechanicalReduction>101</mechanicalReduction>
    </actuator>
  </transmission>

  <!-- left_arm part -->
  <link name="link_09">
    <inertial>
      <mass value="2.8163"/>
      <origin rpy="0 0 0" xyz="0.0002952 -0.0341703 0.076461"/>
      <inertia ixx="0.0057" ixy="0.0" ixz="0.0" iyy="0.0055" iyz="-0.0005" izz="0.0044"/>
    </inertial>
    <collision>
      <origin rpy="1.57 0 0" xyz="0.0002952 -0.0341703 0.076461"/>
      <geometry>
        <cylinder length="0.083" radius="0.04"/>
      </geometry>
    </collision>
    <visual>
      <origin rpy="0 0 0" xyz="0 -0.075 0.083"/>
      <geometry>
        <!--<cylinder length="0.083" radius="0.04"/>-->
        <mesh filename="package://dualarm_description/meshes/dualarm/l_arm1.STL" scale="0.001 0.001 0.001" />
      </geometry>
    </visual>
  </link>
  <joint name="link_02_link_09" type="revolute">
    <axis xyz="0 0 -1"/>
    <limit effort="100" lower="-1.5708" upper="0.5236" velocity="1"/>
    <origin rpy="0 0 0" xyz="0 -0.125 0.217"/>
    <parent link="link_02"/>
    <child link="link_09"/>
  </joint>
  <transmission name="trans_link_02_link_09">
    <type>transmission_interface/SimpleTransmission</type>
    <joint name="link_02_link_09">
      <hardwareInterface>hardware_interface/EffortJointInterface</hardwareInterface>
    </joint>
    <actuator name="motor_link_02_link_09">
      <hardwareInterface>hardware_interface/EffortJointInterface</hardwareInterface>
      <mechanicalReduction>101</mechanicalReduction>
    </actuator>
  </transmission>
  <link name="link_10">
    <inertial>
      <mass value="3.213"/>
      <origin rpy="0 0 0" xyz="0.0112502 -0.0950175 0"/>
      <inertia ixx="0.0088" ixy="-0.0115" ixz="0.0289" iyy="0.0049" iyz="-0.797" izz="0.0089"/>
    </inertial>
    <collision>
      <origin rpy="0 -1.57 0" xyz="0.0112502 -0.0950175 0"/>
      <geometry>
        <cylinder length="0.09" radius="0.04"/>
      </geometry>
    </collision>
    <visual>
      <origin rpy="0 0 0" xyz="0 -0.11 -0.00"/>
      <geometry>
      	<mesh filename="package://dualarm_description/meshes/dualarm/l_arm2.STL" scale="0.001 0.001 0.001" />
        <!--<cylinder length="0.09" radius="0.04"/>-->
      </geometry>
    </visual>
  </link>
  <joint name="link_09_link_10" type="revolute">
    <axis xyz="0 -1 0"/>
    <limit effort="100" lower="-1.5708" upper="0.7854" velocity="1"/>
    <origin rpy="0 0 0" xyz="0 -0.09 0.083"/>
    <parent link="link_09"/>
    <child link="link_10"/>
  </joint>
  <transmission name="trans_link_09_link_10">
    <type>transmission_interface/SimpleTransmission</type>
    <joint name="link_09_link_10">
      <hardwareInterface>hardware_interface/EffortJointInterface</hardwareInterface>
    </joint>
    <actuator name="motor_link_09_link_10">
      <hardwareInterface>hardware_interface/EffortJointInterface</hardwareInterface>
      <mechanicalReduction>101</mechanicalReduction>
    </actuator>
  </transmission>
  <link name="link_11">
    <inertial>
      <mass value="2.4856"/>
      <origin rpy="0 0 0" xyz="0.0015675 -0.0003615 -0.1633768"/>
      <inertia ixx="0.0103" ixy="0.0" ixz="0.0007" iyy="0.0112" iyz="0.0007" izz="0.003"/>
    </inertial>
    <collision>
      <origin rpy="0 0 0" xyz="0.0015675 -0.0003615 -0.1633768"/>
      <geometry>
        <cylinder length="0.242" radius="0.05"/>
      </geometry>
    </collision>
    <visual>
      <origin rpy="0 0 0" xyz="0 0 -0.242"/>
      <geometry>
        <!--<cylinder length="0.242" radius="0.05"/>-->
        <mesh filename="package://dualarm_description/meshes/dualarm/l_arm3.STL" scale="0.001 0.001 0.001" />
      </geometry>
    </visual>
  </link>
  <joint name="link_10_link_11" type="revolute">
    <axis xyz="1 0 0"/>
    <limit effort="100" lower="-1.5708" upper="0.349" velocity="1"/>
    <origin rpy="0 0 0" xyz="0 -0.11 0"/>
    <parent link="link_10"/>
    <child link="link_11"/>
  </joint>
  <transmission name="trans_link_10_link_11">
    <type>transmission_interface/SimpleTransmission</type>
    <joint name="link_10_link_11">
      <hardwareInterface>hardware_interface/EffortJointInterface</hardwareInterface>
    </joint>
    <actuator name="motor_link_10_link_11">
      <hardwareInterface>hardware_interface/EffortJointInterface</hardwareInterface>
      <mechanicalReduction>101</mechanicalReduction>
    </actuator>
  </transmission>
  <link name="link_12">
    <inertial>
      <mass value="1.8893"/>
      <origin rpy="0 0 0" xyz="0.0219475 0.008888 -0.1347982"/>
      <inertia ixx="0.0067" ixy="0.0" ixz="-0.0006" iyy="0.006" iyz="0.0" izz="0.0023"/>
    </inertial>
    <collision>
      <origin rpy="-1.57 0 0" xyz="0.0219475 0.008888 -0.1347982"/>
      <geometry>
        <cylinder length="0.158" radius="0.05"/>
      </geometry>
    </collision>
    <visual>
      <origin rpy="0 0 0" xyz="-0.0245 -0.00175 -0.158"/>
      <geometry>
        <!--<cylinder length="0.158" radius="0.05"/>-->
        <mesh filename="package://dualarm_description/meshes/dualarm/l_arm4.STL" scale="0.001 0.001 0.001" />
      </geometry>
    </visual>
  </link>
  <joint name="link_11_link_12" type="revolute">
    <axis xyz="0 0 -1"/>
    <limit effort="100" lower="-1.5708" upper="1.5708" velocity="1"/>
    <origin rpy="0 0 0" xyz="0 0 -0.242"/>
    <parent link="link_11"/>
    <child link="link_12"/>
  </joint>
  <transmission name="trans_link_11_link_12">
    <type>transmission_interface/SimpleTransmission</type>
    <joint name="link_11_link_12">
      <hardwareInterface>hardware_interface/EffortJointInterface</hardwareInterface>
    </joint>
    <actuator name="motor_link_11_link_12">
      <hardwareInterface>hardware_interface/EffortJointInterface</hardwareInterface>
      <mechanicalReduction>101</mechanicalReduction>
    </actuator>
  </transmission>
  <link name="link_13">
    <inertial>
      <mass value="1.8666"/>
      <origin rpy="0 0 0" xyz="0.0282566 0.0026831 -0.1626786"/>
      <inertia ixx="0.0077" ixy="0.0" ixz="0.0003" iyy="0.007" iyz="0.0008" izz="0.0022"/>
    </inertial>
    <collision>
      <origin rpy="0 0 0" xyz="0.0282566 0.0026831 -0.1626786"/>
      <geometry>
        <cylinder length="0.158" radius="0.05"/>
      </geometry>
    </collision>
    <visual>
      <origin rpy="0 0 0" xyz="0 0 0"/>
      <geometry>
        <!--<cylinder length="0.158" radius="0.05"/>-->
        <mesh filename="package://dualarm_description/meshes/dualarm/l_arm5.STL" scale="0.001 0.001 0.001" />
      </geometry>
    </visual>
  </link>
  <joint name="link_12_link_13" type="revolute">
    <axis xyz="0 -1 0"/>
    <limit effort="100" lower="0" upper="2.3562" velocity="1"/>
    <origin rpy="0 0 0" xyz="-0.0245 -0.00175 -0.158"/>
    <parent link="link_12"/>
    <child link="link_13"/>
  </joint>
  <transmission name="trans_link_12_link_13">
    <type>transmission_interface/SimpleTransmission</type>
    <joint name="link_12_link_13">
      <hardwareInterface>hardware_interface/EffortJointInterface</hardwareInterface>
    </joint>
    <actuator name="motor_link_12_link_13">
      <hardwareInterface>hardware_interface/EffortJointInterface</hardwareInterface>
      <mechanicalReduction>101</mechanicalReduction>
    </actuator>
  </transmission>
  <link name="link_14">
    <inertial>
      <mass value="0.0646"/>
      <origin rpy="0 0 0" xyz="0 0.0027174 -0.0051051"/>
      <inertia ixx="0.0" ixy="0.0" ixz="0.0" iyy="0.0" iyz="0.0" izz="0.0"/>
    </inertial>
    <collision>
      <origin rpy="0 0 0" xyz="0 0.0027174 -0.0051051"/>
      <geometry>
        <cylinder length="0.01" radius="0.05"/>
      </geometry>
    </collision>
    <visual>
      <origin rpy="3.14 0 0" xyz="-0.032 0.034 0.085"/>
      <geometry>
        <!--<cylinder length="0.01" radius="0.05"/>-->
        <mesh filename="package://dualarm_description/meshes/dualarm/link6.STL" scale="0.001 0.001 0.001" />
      </geometry>
    </visual>
  </link>
  <joint name="link_13_link_14" type="revolute">
    <axis xyz="0 0 -1"/>
    <limit effort="100" lower="-0.7854" upper="0.7854" velocity="1"/>
    <origin rpy="0 0 0" xyz="0.0245 0.00175 -0.235"/>
    <parent link="link_13"/>
    <child link="link_14"/>
  </joint>
  <transmission name="trans_link_13_link_14">
    <type>transmission_interface/SimpleTransmission</type>
    <joint name="link_13_link_14">
      <hardwareInterface>hardware_interface/EffortJointInterface</hardwareInterface>
    </joint>
    <actuator name="motor_link_13_link_14">
      <hardwareInterface>hardware_interface/EffortJointInterface</hardwareInterface>
      <mechanicalReduction>101</mechanicalReduction>
    </actuator>
  </transmission>
  <!-- for gazebo -->
  <gazebo>
    <plugin name="gazebo_ros_control" filename="libgazebo_ros_control.so">
      <robotNamespace>/dualarm</robotNamespace>
      <robotSimType>gazebo_ros_control/DefaultRobotHWSim</robotSimType>
      <controlPeriod>0.001</controlPeriod>
      <legacyModeNS>true</legacyModeNS>
    </plugin>
  </gazebo>
</robot>

