<?xml version="1.0"?>
<robot name="dualarm" xmlns:xacro="http://www.ros.org/wiki/xacro" >

	<xacro:include filename="$(find dualarm_description)/urdf/link_to_joint.xacro" />
	<xacro:include filename="$(find dualarm_description)/urdf/robot_parameter.xacro" />
	<xacro:include filename="$(find dualarm_description)/urdf/dual_arm.gazebo.xacro" />

	<!-- Base parts -->
	<link name = "world"/>
	<joint name="base_joint" type="fixed">
		<origin
				xyz="0 0 0"
				rpy="0 0 0"/>
		<parent
				link="world"/>
		<child
				link="dual_arm_base_link"/>
	</joint>

	<link name="dual_arm_base_link"/>

	<joint name="dual_arm_base_joint" type="fixed">
		<origin
			xyz="0 0 0"
			rpy="0 0 0"/>
		<parent
			link="dual_arm_base_link"/>
		<child
			link="${base_link_name}"/>
	</joint>

	<link name="${base_link_name}">
		<inertial>
			<mass value="${base_link_mass}" />
			<origin
					rpy="0 0 0"
					xyz="0 0 0.15" />
			<inertia
					ixx="${base_link_ixx}"
					ixy="${base_link_ixy}"
					ixz="${base_link_ixz}"
					iyy="${base_link_iyy}"
					iyz="${base_link_iyz}"
					izz="${base_link_izz}" />
		</inertial>
		<visual>
			<origin
					rpy="0 0 0"
					xyz="0 0 0" />
			<geometry>
				<mesh
						filename="package://dualarm_description/meshes/stl/base.STL"
						scale="0.001 0.001 0.001"/>
			</geometry>
		</visual>
	</link>

	<!-- waist part -->
	<joint name="dualarm_joint1" type="revolute">
		<axis xyz="0 0 -1" />
		<limit
				effort="300"
				lower="-1.5708"
				upper="1.5708"
				velocity="${2*M_PI}" />
		<origin
				rpy="0 0 0"
				xyz="0 0 0.3031" />
		<parent
				link="${base_link_name}" />
		<child
				link="${waist_link_01_name}" />
		<dynamics damping="0.01" friction="0.1"/>0
	</joint>
	<transmission
			name="trans_dualarm_joint1">
		<type>transmission_interface/SimpleTransmission</type>
		<joint
				name="dualarm_joint1">
			<hardwareInterface>hardware_interface/EffortJointInterface</hardwareInterface>
		</joint>
		<actuator
				name="motor_dualarm_joint1">
			<hardwareInterface>hardware_interface/EffortJointInterface</hardwareInterface>
			<mechanicalReduction>1</mechanicalReduction>
		</actuator>
	</transmission>

	<link name="${waist_link_01_name}">
		<inertial>
			<mass value="${waist_link_01_mass}" />
			<origin
					rpy="0 0 0"
					xyz="-0.0001211 -0.0015722 0.1519998" />
			<inertia
					ixx="${waist_link_01_ixx}"
					ixy="${waist_link_01_ixy}"
					ixz="${waist_link_01_ixz}"
					iyy="${waist_link_01_iyy}"
					iyz="${waist_link_01_iyz}"
					izz="${waist_link_01_izz}" />
		</inertial>
		<visual>
			<origin
					rpy="0 0 0"
					xyz="0 0 0" />
			<geometry>
				<mesh
						filename="package://dualarm_description/meshes/stl/waist1.STL"
						scale="0.001 0.001 0.001"/>
			</geometry>
		</visual>
	</link>

	<joint name="dualarm_joint2" type="revolute">
		<axis xyz="0 -1 0" />
		<limit
				effort="300"
				lower="0.2618"
				upper="-1.2217"
				velocity="${2*M_PI}" />
		<origin
				rpy="0 0 0"
				xyz="0 0 0.1969" />
		<parent
				link="${waist_link_01_name}" />
		<child
				link="${waist_link_02_name}" />
		<dynamics damping="1" friction="1"/>
	</joint>
	<transmission
			name="trans_dualarm_joint2">
		<type>transmission_interface/SimpleTransmission</type>
		<joint
				name="dualarm_joint2">
			<hardwareInterface>hardware_interface/EffortJointInterface</hardwareInterface>
		</joint>
		<actuator
				name="motor_dualarm_joint2">
			<hardwareInterface>hardware_interface/EffortJointInterface</hardwareInterface>
			<mechanicalReduction>1</mechanicalReduction>
		</actuator>
	</transmission>

	<link name="${waist_link_02_name}">
		<inertial>
			<mass value="${waist_link_02_mass}" />
			<origin
					rpy="0 0 0"
					xyz="0.0054 0.0042 0.119" />
			<inertia
					ixx="${waist_link_02_ixx}"
					ixy="${waist_link_02_ixy}"
					ixz="${waist_link_02_ixz}"
					iyy="${waist_link_02_iyy}"
					iyz="${waist_link_02_iyz}"
					izz="${waist_link_02_izz}" />
		</inertial>
		<visual>
			<origin
					rpy="0 0 0"
					xyz="0 0 0" />
			<geometry>
				<mesh
						filename="package://dualarm_description/meshes/stl/waist2.STL"
						scale="0.001 0.001 0.001"/>
			</geometry>
		</visual>
	</link>

	<!--
	right_arm part
	-->
	<joint name="dualarm_joint3" type="revolute">
		<axis xyz="0 0 -1" />
		<limit
				effort="300"
				lower="-1.5708"
				upper="0.5236"
				velocity="${2*M_PI}" />
		<origin
				rpy="0 0 0"
				xyz="0 -0.125 0.18565" />
		<parent
				link="${waist_link_02_name}" />
		<child
				link="${r_arm_link_01_name}" />
		<dynamics damping="0.01" friction="0.1"/>
	</joint>
	<transmission
			name="trans_dualarm_joint3">
		<type>transmission_interface/SimpleTransmission</type>
		<joint
				name="dualarm_joint3">
			<hardwareInterface>hardware_interface/EffortJointInterface</hardwareInterface>
		</joint>
		<actuator
				name="motor_dualarm_joint3">
			<hardwareInterface>hardware_interface/EffortJointInterface</hardwareInterface>
			<mechanicalReduction>1</mechanicalReduction>
		</actuator>
	</transmission>

	<link name="${r_arm_link_01_name}">
		<inertial>
			<mass value="${r_arm_link_01_mass}" />
			<origin
					rpy="0 0 0"
					xyz="-0.0007018 -0.0179392 0.0955618" />
			<inertia
					ixx="${r_arm_link_01_ixx}"
					ixy="${r_arm_link_01_ixy}"
					ixz="${r_arm_link_01_ixz}"
					iyy="${r_arm_link_01_iyy}"
					iyz="${r_arm_link_01_iyz}"
					izz="${r_arm_link_01_izz}" />
		</inertial>
		<visual>
			<origin
					rpy="0 0 0"
					xyz="0 0 0" />
			<geometry>
				<mesh
						filename="package://dualarm_description/meshes/stl/r1.STL"
						scale="0.001 0.001 0.001"/>
			</geometry>
		</visual>
	</link>

	<joint name="dualarm_joint4" type="revolute">
		<axis xyz="0 1 0" />
		<limit
				effort="300"
				lower="-1.5708"
				upper="0.7854"
				velocity="${2*M_PI}" />
		<origin
				rpy="0 0 0"
				xyz="0 -0.05265 0.11435" />
		<parent
				link="${r_arm_link_01_name}" />
		<child
				link="${r_arm_link_02_name}" />
		<dynamics damping="0.01" friction="0.1"/>
	</joint>
	<transmission
			name="trans_dualarm_joint4">
		<type>transmission_interface/SimpleTransmission</type>
		<joint
				name="dualarm_joint4">
			<hardwareInterface>hardware_interface/EffortJointInterface</hardwareInterface>
		</joint>
		<actuator
				name="motor_dualarm_joint4">
			<hardwareInterface>hardware_interface/EffortJointInterface</hardwareInterface>
			<mechanicalReduction>1</mechanicalReduction>
		</actuator>
	</transmission>

	<link name="${r_arm_link_02_name}">
		<inertial>
			<mass value="${r_arm_link_02_mass}" />
			<origin
					rpy="0 0 0"
					xyz="-0.00021 -0.1153861 0.00077" />
			<inertia
					ixx="${r_arm_link_02_ixx}"
					ixy="${r_arm_link_02_ixy}"
					ixz="${r_arm_link_02_ixz}"
					iyy="${r_arm_link_02_iyy}"
					iyz="${r_arm_link_02_iyz}"
					izz="${r_arm_link_02_izz}" />
		</inertial>
		<visual>
			<origin
					rpy="0 0 0"
					xyz="0 0 0" />
			<geometry>
				<mesh
						filename="package://dualarm_description/meshes/stl/r2.STL"
						scale="0.001 0.001 0.001"/>
			</geometry>
		</visual>
	</link>

	<joint name="dualarm_joint5" type="revolute">
		<axis xyz="1 0 0" />
		<limit
				effort="300"
				lower="-1.5708"
				upper="0.349"
				velocity="${2*M_PI}" />
		<origin
				rpy="0 0 0"
				xyz="0 -0.14735 0" />
		<parent
				link="${r_arm_link_02_name}" />
		<child
				link="${r_arm_link_03_name}" />
		<dynamics damping="0.01" friction="0.1"/>
	</joint>
	<transmission
			name="trans_dualarm_joint5">
		<type>transmission_interface/SimpleTransmission</type>
		<joint
				name="dualarm_joint5">
			<hardwareInterface>hardware_interface/EffortJointInterface</hardwareInterface>
		</joint>
		<actuator
				name="motor_dualarm_joint5">
			<hardwareInterface>hardware_interface/EffortJointInterface</hardwareInterface>
			<mechanicalReduction>1</mechanicalReduction>
		</actuator>
	</transmission>

	<link name="${r_arm_link_03_name}">
		<inertial>
			<mass value="${r_arm_link_03_mass}" />
			<origin
					rpy="0 0 0"
					xyz="-0.0025431 -0.0001796 -0.1503879" />
			<inertia
					ixx="${r_arm_link_03_ixx}"
					ixy="${r_arm_link_03_ixy}"
					ixz="${r_arm_link_03_ixz}"
					iyy="${r_arm_link_03_iyy}"
					iyz="${r_arm_link_03_iyz}"
					izz="${r_arm_link_03_izz}" />
		</inertial>
		<visual>
			<origin
					rpy="0 0 0"
					xyz="0 0 0" />
			<geometry>
				<mesh
						filename="package://dualarm_description/meshes/stl/r3.STL"
						scale="0.001 0.001 0.001"/>
			</geometry>
		</visual>
	</link>

	<joint name="dualarm_joint6" type="revolute">
		<axis xyz="0 0 1" />
		<limit
				effort="300"
				lower="-1.5708"
				upper="1.5708"
				velocity="${2*M_PI}" />
		<origin
				rpy="0 0 0"
				xyz="0 0 -0.21425" />
		<parent
				link="${r_arm_link_03_name}" />
		<child
				link="${r_arm_link_04_name}" />
		<dynamics damping="0.01" friction="0.1"/>
	</joint>
	<transmission
			name="trans_dualarm_joint6">
		<type>transmission_interface/SimpleTransmission</type>
		<joint
				name="dualarm_joint6">
			<hardwareInterface>hardware_interface/EffortJointInterface</hardwareInterface>
		</joint>
		<actuator
				name="motor_dualarm_joint6">
			<hardwareInterface>hardware_interface/EffortJointInterface</hardwareInterface>
			<mechanicalReduction>1</mechanicalReduction>
		</actuator>
	</transmission>

	<link name="${r_arm_link_04_name}">
		<inertial>
			<mass value="${r_arm_link_04_mass}" />
			<origin
					rpy="0 0 0"
					xyz="-0.0191 0.0026 -0.1364" />
			<inertia
					ixx="${r_arm_link_04_ixx}"
					ixy="${r_arm_link_04_ixy}"
					ixz="${r_arm_link_04_ixz}"
					iyy="${r_arm_link_04_iyy}"
					iyz="${r_arm_link_04_iyz}"
					izz="${r_arm_link_04_izz}" />
		</inertial>
		<visual>
			<origin
					rpy="0 0 0"
					xyz="0 0 0" />
			<geometry>
				<mesh
						filename="package://dualarm_description/meshes/stl/r4.STL"
						scale="0.001 0.001 0.001"/>
			</geometry>
		</visual>
	</link>

	<joint name="dualarm_joint7" type="revolute">
		<axis xyz="0 1 0" />
		<limit
				effort="300"
				lower="-1.5708"
				upper="0.7854"
				velocity="${2*M_PI}" />
		<origin
				rpy="0 0 0"
				xyz="-0.0245 0 -0.18575" />
		<parent
				link="${r_arm_link_04_name}" />
		<child
				link="${r_arm_link_05_name}" />
		<dynamics damping="0.01" friction="0.1"/>
	</joint>
	<transmission
			name="trans_dualarm_joint7">
		<type>transmission_interface/SimpleTransmission</type>
		<joint
				name="dualarm_joint7">
			<hardwareInterface>hardware_interface/EffortJointInterface</hardwareInterface>
		</joint>
		<actuator
				name="motor_dualarm_joint7">
			<hardwareInterface>hardware_interface/EffortJointInterface</hardwareInterface>
			<mechanicalReduction>1</mechanicalReduction>
		</actuator>
	</transmission>

	<link name="${r_arm_link_05_name}">
		<inertial>
			<mass value="${r_arm_link_05_mass}" />
			<origin
					rpy="0 0 0"
					xyz="-0.0023 0.0022 -0.0965" />
			<inertia
					ixx="${r_arm_link_05_ixx}"
					ixy="${r_arm_link_05_ixy}"
					ixz="${r_arm_link_05_ixz}"
					iyy="${r_arm_link_05_iyy}"
					iyz="${r_arm_link_05_iyz}"
					izz="${r_arm_link_05_izz}" />
		</inertial>
		<visual>
			<origin
					rpy="0 0 0"
					xyz="0 0 0" />
			<geometry>
				<mesh
						filename="package://dualarm_description/meshes/stl/r5.STL"
						scale="0.001 0.001 0.001"/>
			</geometry>
		</visual>
	</link>

	<joint name="dualarm_joint8" type="revolute">
		<axis xyz="0 0 1" />
		<limit
				effort="300"
				lower="-0.7854"
				upper="0.7854"
				velocity="${2*M_PI}" />
		<origin
				rpy="0 0 0"
				xyz="0.0245 0 -0.14" />
		<parent
				link="${r_arm_link_05_name}" />
		<child
				link="${r_arm_link_06_name}" />
		<dynamics damping="0.01" friction="0.1"/>
	</joint>
	<transmission
			name="trans_dualarm_joint8">
		<type>transmission_interface/SimpleTransmission</type>
		<joint
				name="dualarm_joint8">
			<hardwareInterface>hardware_interface/EffortJointInterface</hardwareInterface>
		</joint>
		<actuator
				name="motor_dualarm_joint8">
			<hardwareInterface>hardware_interface/EffortJointInterface</hardwareInterface>
			<mechanicalReduction>1</mechanicalReduction>
		</actuator>
	</transmission>

	<link name="${r_arm_link_06_name}">
		<inertial>
			<mass value="${r_arm_link_06_mass}" />
			<origin
					rpy="0 0 0"
					xyz="0.0036 -0.0004 -0.0746" />
			<inertia
					ixx="${r_arm_link_06_ixx}"
					ixy="${r_arm_link_06_ixy}"
					ixz="${r_arm_link_06_ixz}"
					iyy="${r_arm_link_06_iyy}"
					iyz="${r_arm_link_06_iyz}"
					izz="${r_arm_link_06_izz}" />
		</inertial>
		<visual>
			<origin
					rpy="0 0 0"
					xyz="0 0 0" />
			<geometry>
				<mesh
						filename="package://dualarm_description/meshes/stl/r6.STL"
						scale="0.001 0.001 0.001"/>
			</geometry>
		</visual>
	</link>

	<joint name="dualarm_joint9" type="revolute">
		<axis xyz="1 0 0" />
		<limit
				effort="300"
				lower="-1.5708"
				upper="1.5708"
				velocity="${2*M_PI}" />
		<origin
				rpy="0 0 0"
				xyz="0 0 -0.091" />
		<parent
				link="${r_arm_link_06_name}" />
		<child
				link="${r_arm_link_hand_1}" />
		<dynamics damping="0.01" friction="0.1"/>
	</joint>
	<transmission
			name="trans_dualarm_joint9">
		<type>transmission_interface/SimpleTransmission</type>
		<joint
				name="dualarm_joint9">
			<hardwareInterface>hardware_interface/EffortJointInterface</hardwareInterface>
		</joint>
		<actuator
				name="motor_dualarm_joint9">
			<hardwareInterface>hardware_interface/EffortJointInterface</hardwareInterface>
			<mechanicalReduction>1</mechanicalReduction>
		</actuator>
	</transmission>

	<link name="${r_arm_link_hand_1}">
		<inertial>
			<mass value="${r_arm_link_07_1_mass}" />
			<origin
					rpy="0 0 0"
					xyz="0.0079 0.0 -0.0345" />
			<inertia
					ixx="${r_arm_link_07_1_ixx}"
					ixy="${r_arm_link_07_1_ixy}"
					ixz="${r_arm_link_07_1_ixz}"
					iyy="${r_arm_link_07_1_iyy}"
					iyz="${r_arm_link_07_1_iyz}"
					izz="${r_arm_link_07_1_izz}" />
		</inertial>
		<visual>
			<origin
					rpy="0 0 0"
					xyz="0 0 0" />
			<geometry>
				<mesh
						filename="package://dualarm_description/meshes/stl/wrist_ft_R.STL"
						scale="0.001 0.001 0.001"/>
			</geometry>
		</visual>
	</link>

	<joint name="ft_sensor_joint_R" type="fixed">
		<parent link="${r_arm_link_hand_1}"/>
		<child link="${r_arm_link_hand_2}"/>
		<origin
				rpy="0 0 0"
				xyz="0 0 -0.067"/>
		<limit effort="1000" velocity="100" lower="0" upper="0"/>
	</joint>

	<link name="${r_arm_link_hand_2}">
		<inertial>
			<mass value="${r_arm_link_07_2_mass}" />
			<origin
					rpy="0 0 0"
					xyz="0.0112 0.0129 -0.1085" />
			<inertia
					ixx="${r_arm_link_07_2_ixx}"
					ixy="${r_arm_link_07_2_ixy}"
					ixz="${r_arm_link_07_2_ixz}"
					iyy="${r_arm_link_07_2_iyy}"
					iyz="${r_arm_link_07_2_iyz}"
					izz="${r_arm_link_07_2_izz}" />
		</inertial>
		<visual>
			<origin
					rpy="0 0 0"
					xyz="0 0 0" />
			<geometry>
				<mesh
						filename="package://dualarm_description/meshes/stl/allegro_ft.STL"
						scale="1 1 1"/>
			</geometry>
		</visual>
		<!--<collision name='collision'>
			<geometry>
				<mesh filename="package://dualarm_description/meshes/collision/allegro.dae"
					  scale="1 1 1"/>
			</geometry>
			<surface>
				<friction>
					<ode>
						<mu>100</mu>
						<mu2>100</mu2>
					</ode>
				</friction>
			</surface>
		</collision>-->
	</link>

	<joint name="dualarm_R_end" type="fixed">
		<origin
				xyz="0 0 -0.090"
				rpy="0 ${M_PI/2} 0"/>
		<parent link="${r_arm_link_hand_2}"/>
		<child link="dualarm_R_end_frame" />
	</joint>

	<link name="dualarm_R_end_frame"/>


	<!-- left_arm part-->
	<joint name="dualarm_joint10" type="revolute">
		<axis xyz="0 0 -1" />
		<limit
				effort="300"
				lower="-0.5236"
				upper="1.5708"
				velocity="${2*M_PI}" />
		<origin
				rpy="0 0 0"
				xyz="0 0.125 0.18565" />
		<parent
				link="${waist_link_02_name}" />
		<child
				link="${l_arm_link_01_name}" />
		<dynamics damping="0.01" friction="0.1"/>
	</joint>
	<transmission
			name="trans_dualarm_joint10">
		<type>transmission_interface/SimpleTransmission</type>
		<joint
				name="dualarm_joint10">
			<hardwareInterface>hardware_interface/EffortJointInterface</hardwareInterface>
		</joint>
		<actuator
				name="motor_dualarm_joint10">
			<hardwareInterface>hardware_interface/EffortJointInterface</hardwareInterface>
			<mechanicalReduction>1</mechanicalReduction>
		</actuator>
	</transmission>

	<link name="${l_arm_link_01_name}">
		<inertial>
			<mass value="${l_arm_link_01_mass}" />
			<origin
					rpy="0 0 0"
					xyz="-0.0009 0.0179 0.0957" />
			<inertia
					ixx="${l_arm_link_01_ixx}"
					ixy="${l_arm_link_01_ixy}"
					ixz="${l_arm_link_01_ixz}"
					iyy="${l_arm_link_01_iyy}"
					iyz="${l_arm_link_01_iyz}"
					izz="${l_arm_link_01_izz}" />
		</inertial>
		<visual>
			<origin
					rpy="0 0 0"
					xyz="0 0 0" />
			<geometry>
				<mesh
						filename="package://dualarm_description/meshes/stl/l1.STL"
						scale="0.001 0.001 0.001"/>
			</geometry>
		</visual>
	</link>

	<joint name="dualarm_joint11" type="revolute">
		<axis xyz="0 -1 0" />
		<limit
				effort="300"
				lower="-0.7854"
				upper="1.5708"
				velocity="${2*M_PI}" />
		<origin
				rpy="0 0 0"
				xyz="0 0.05265 0.11435" />
		<parent
				link="${l_arm_link_01_name}" />
		<child
				link="${l_arm_link_02_name}" />
		<dynamics damping="0.01" friction="0.1"/>
	</joint>
	<transmission
			name="trans_dualarm_joint11">
		<type>transmission_interface/SimpleTransmission</type>
		<joint
				name="dualarm_joint11">
			<hardwareInterface>hardware_interface/EffortJointInterface</hardwareInterface>
		</joint>
		<actuator
				name="motor_dualarm_joint11">
			<hardwareInterface>hardware_interface/EffortJointInterface</hardwareInterface>
			<mechanicalReduction>1</mechanicalReduction>
		</actuator>
	</transmission>

	<link name="${l_arm_link_02_name}">
		<inertial>
			<mass value="${l_arm_link_02_mass}" />
			<origin
					rpy="0 0 0"
					xyz="0.0009 0.1131 0.0005" />
			<inertia
					ixx="${l_arm_link_02_ixx}"
					ixy="${l_arm_link_02_ixy}"
					ixz="${l_arm_link_02_ixz}"
					iyy="${l_arm_link_02_iyy}"
					iyz="${l_arm_link_02_iyz}"
					izz="${l_arm_link_02_izz}" />
		</inertial>
		<visual>
			<origin
					rpy="0 0 0"
					xyz="0 0 0" />
			<geometry>
				<mesh
						filename="package://dualarm_description/meshes/stl/l2.STL"
						scale="0.001 0.001 0.001"/>
			</geometry>
		</visual>
	</link>

	<joint name="dualarm_joint12" type="revolute">
		<axis xyz="1 0 0" />
		<limit
				effort="200"
				lower="-0.349"
				upper="1.5708"
				velocity="${2*M_PI}" />
		<origin
				rpy="0 0 0"
				xyz="0 0.14735 0" />
		<parent
				link="${l_arm_link_02_name}" />
		<child
				link="${l_arm_link_03_name}" />
		<dynamics damping="0.01" friction="0.1"/>
	</joint>
	<transmission
			name="trans_dualarm_joint12">
		<type>transmission_interface/SimpleTransmission</type>
		<joint
				name="dualarm_joint12">
			<hardwareInterface>hardware_interface/EffortJointInterface</hardwareInterface>
		</joint>
		<actuator
				name="motor_dualarm_joint12">
			<hardwareInterface>hardware_interface/EffortJointInterface</hardwareInterface>
			<mechanicalReduction>1</mechanicalReduction>
		</actuator>
	</transmission>

	<link name="${l_arm_link_03_name}">
		<inertial>
			<mass value="${l_arm_link_03_mass}" />
			<origin
					rpy="0 0 0"
					xyz="-0.0024 0.0002 -0.1504" />
			<inertia
					ixx="${l_arm_link_03_ixx}"
					ixy="${l_arm_link_03_ixy}"
					ixz="${l_arm_link_03_ixz}"
					iyy="${l_arm_link_03_iyy}"
					iyz="${l_arm_link_03_iyz}"
					izz="${l_arm_link_03_izz}" />
		</inertial>
		<visual>
			<origin
					rpy="0 0 0"
					xyz="0 0 0" />
			<geometry>
				<mesh
						filename="package://dualarm_description/meshes/stl/l3.STL"
						scale="0.001 0.001 0.001"/>
			</geometry>
		</visual>
	</link>

	<joint name="dualarm_joint13" type="revolute">
		<axis xyz="0 0 1" />
		<limit
				effort="200"
				lower="-1.5708"
				upper="1.5708"
				velocity="${2*M_PI}" />
		<origin
				rpy="0 0 0"
				xyz="0 0 -0.21425" />
		<parent
				link="${l_arm_link_03_name}" />
		<child
				link="${l_arm_link_04_name}" />
		<dynamics damping="0.01" friction="0.1"/>
	</joint>
	<transmission
			name="trans_dualarm_joint13">
		<type>transmission_interface/SimpleTransmission</type>
		<joint
				name="dualarm_joint13">
			<hardwareInterface>hardware_interface/EffortJointInterface</hardwareInterface>
		</joint>
		<actuator
				name="motor_dualarm_joint13">
			<hardwareInterface>hardware_interface/EffortJointInterface</hardwareInterface>
			<mechanicalReduction>1</mechanicalReduction>
		</actuator>
	</transmission>

	<link name="${l_arm_link_04_name}">
		<inertial>
			<mass value="${l_arm_link_04_mass}" />
			<origin
					rpy="0 0 0"
					xyz="-0.0189 -0.0027 -0.136" />
			<inertia
					ixx="${l_arm_link_04_ixx}"
					ixy="${l_arm_link_04_ixy}"
					ixz="${l_arm_link_04_ixz}"
					iyy="${l_arm_link_04_iyy}"
					iyz="${l_arm_link_04_iyz}"
					izz="${l_arm_link_04_izz}" />
		</inertial>
		<visual>
			<origin
					rpy="0 0 0"
					xyz="0 0 0" />
			<geometry>
				<mesh
						filename="package://dualarm_description/meshes/stl/l4.STL"
						scale="0.001 0.001 0.001"/>
			</geometry>
		</visual>
	</link>

	<joint name="dualarm_joint14" type="revolute">
		<axis xyz="0 -1 0" />
		<limit
				effort="300"
				lower="-0.7804"
				upper="1.5708"
				velocity="${2*M_PI}" />
		<origin
				rpy="0 0 0"
				xyz="-0.0245 0 -0.18575" />
		<parent
				link="${l_arm_link_04_name}" />
		<child
				link="${l_arm_link_05_name}" />
		<dynamics damping="0.01" friction="0.1"/>
	</joint>
	<transmission
			name="trans_dualarm_joint14">
		<type>transmission_interface/SimpleTransmission</type>
		<joint
				name="dualarm_joint14">
			<hardwareInterface>hardware_interface/EffortJointInterface</hardwareInterface>
		</joint>
		<actuator
				name="motor_dualarm_joint14">
			<hardwareInterface>hardware_interface/EffortJointInterface</hardwareInterface>
			<mechanicalReduction>1</mechanicalReduction>
		</actuator>
	</transmission>

	<link name="${l_arm_link_05_name}">
		<inertial>
			<mass value="${l_arm_link_05_mass}" />
			<origin
					rpy="0 0 0"
					xyz="-0.0023 -0.0014 -0.0965" />
			<inertia
					ixx="${l_arm_link_05_ixx}"
					ixy="${l_arm_link_05_ixy}"
					ixz="${l_arm_link_05_ixz}"
					iyy="${l_arm_link_05_iyy}"
					iyz="${l_arm_link_05_iyz}"
					izz="${l_arm_link_05_izz}" />
		</inertial>
		<visual>
			<origin
					rpy="0 0 0"
					xyz="0 0 0" />
			<geometry>
				<mesh
						filename="package://dualarm_description/meshes/stl/l5.STL"
						scale="0.001 0.001 0.001"/>
			</geometry>
		</visual>
	</link>

	<joint name="dualarm_joint15" type="revolute">
		<axis xyz="0 0 1" />
		<limit
				effort="300"
				lower="-${M_PI}"
				upper="${M_PI}"
				velocity="${M_PI}" />
		<origin
				rpy="0 0 0"
				xyz="0.0245 0 -0.14" />
		<parent
				link="${l_arm_link_05_name}" />
		<child
				link="${l_arm_link_06_name}" />
		<dynamics damping="0.01" friction="0.1"/>
	</joint>
	<transmission
			name="trans_dualarm_joint15">
		<type>transmission_interface/SimpleTransmission</type>
		<joint
				name="dualarm_joint15">
			<hardwareInterface>hardware_interface/EffortJointInterface</hardwareInterface>
		</joint>
		<actuator
				name="motor_dualarm_joint15">
			<hardwareInterface>hardware_interface/EffortJointInterface</hardwareInterface>
			<mechanicalReduction>1</mechanicalReduction>
		</actuator>
	</transmission>

	<link name="${l_arm_link_06_name}">
		<inertial>
			<mass value="${l_arm_link_06_mass}" />
			<origin
					rpy="0 0 0"
					xyz="0.0039 -0.0002 -0.08" />
			<inertia
					ixx="${l_arm_link_06_ixx}"
					ixy="${l_arm_link_06_ixy}"
					ixz="${l_arm_link_06_ixz}"
					iyy="${l_arm_link_06_iyy}"
					iyz="${l_arm_link_06_iyz}"
					izz="${l_arm_link_06_izz}" />
		</inertial>
		<visual>
			<origin
					rpy="0 0 0"
					xyz="0 0 0" />
			<geometry>
				<mesh
						filename="package://dualarm_description/meshes/stl/l6.STL"
						scale="0.001 0.001 0.001"/>
			</geometry>
		</visual>
	</link>

	<joint name="dualarm_joint16" type="revolute">
		<axis xyz="1 0 0" />
		<limit
				effort="300"
				lower="-1.5708"
				upper="1.5708"
				velocity="${M_PI}" />
		<origin
				rpy="0 0 0"
				xyz="0 0 -0.091" />
		<parent
				link="${l_arm_link_06_name}" />
		<child
				link="${l_arm_link_hand_1}" />
		<dynamics damping="0.01" friction="0.1"/>
	</joint>
	<transmission
			name="trans_dualarm_joint16">
		<type>transmission_interface/SimpleTransmission</type>
		<joint
				name="dualarm_joint16">
			<hardwareInterface>hardware_interface/EffortJointInterface</hardwareInterface>
		</joint>
		<actuator
				name="motor_dualarm_joint16">
			<hardwareInterface>hardware_interface/EffortJointInterface</hardwareInterface>
			<mechanicalReduction>1</mechanicalReduction>
		</actuator>
	</transmission>

	<link name="${l_arm_link_hand_1}">
		<inertial>
			<mass value="${l_arm_link_07_1_mass}" />
			<origin
					rpy="0 0 0"
					xyz="0.0079 0.0 -0.0345" />
			<inertia
					ixx="${l_arm_link_07_1_ixx}"
					ixy="${l_arm_link_07_1_ixy}"
					ixz="${l_arm_link_07_1_ixz}"
					iyy="${l_arm_link_07_1_iyy}"
					iyz="${l_arm_link_07_1_iyz}"
					izz="${l_arm_link_07_1_izz}" />
		</inertial>
		<visual>
			<origin
					rpy="0 0 0"
					xyz="0 0 0" />
			<geometry>
				<mesh
						filename="package://dualarm_description/meshes/stl/wrist_ft_L.STL"
						scale="0.001 0.001 0.001"/>
			</geometry>
		</visual>
	</link>

	<joint name="ft_sensor_joint_L" type="fixed">
		<parent link="${l_arm_link_hand_1}"/>
		<child link="${l_arm_link_hand_2}"/>
		<origin
				rpy="0 0 0"
				xyz="0 0 -0.067"/>
		<limit effort="1000" velocity="100" lower="0" upper="0"/>
	</joint>

	<link name="${l_arm_link_hand_2}">
		<inertial>
			<mass value="${l_arm_link_07_2_mass}" />
			<origin
					rpy="0 0 0"
					xyz="0.0282 -0.0237 -0.0862" />
			<inertia
					ixx="${l_arm_link_07_2_ixx}"
					ixy="${l_arm_link_07_2_ixy}"
					ixz="${l_arm_link_07_2_ixz}"
					iyy="${l_arm_link_07_2_iyy}"
					iyz="${l_arm_link_07_2_iyz}"
					izz="${l_arm_link_07_2_izz}" />
		</inertial>
		<visual>
			<origin
					rpy="0 0 0"
					xyz="0 0 0" />
			<geometry>
				<mesh
						filename="package://dualarm_description/meshes/stl/lefthand_ft.STL"
						scale="0.001 0.001 0.001"/>
			</geometry>
		</visual>
		<!--<collision name='collision'>
			<geometry>
				<mesh filename="package://dualarm_description/meshes/collision/lefthand_ft.dae"
				scale="0.001 0.001 0.001"/>
			</geometry>
			<surface>
				<friction>
					<ode>
						<mu>100</mu>
						<mu2>100</mu2>
					</ode>
				</friction>
			</surface>
		</collision> -->
	</link>

	<joint name="dualarm_L_end" type="fixed">
		<origin
				xyz="0 0 -0.090"
				rpy="0 ${M_PI/2} 0"/>
		<parent link="${l_arm_link_hand_2}"/>
		<child link="dualarm_L_end_frame" />
	</joint>

	<link name="dualarm_L_end_frame"/>
</robot>
